2024-09-18 12:07:51,120 - saxs_analysis - WARNING - Fit file /Users/tiago/working_PAPERS/SAXS_oligo_Kd/plotly_dash_tests/saxs_binding_equilibria_app_v3/data/fit_nan_21.54434690031882.fit does not exist.
2024-09-18 12:07:51,121 - saxs_analysis - ERROR - KeyError: 'contents' in item 1
2024-09-18 12:07:51,139 - saxs_analysis - ERROR - An error occurred during analysis: nan
Traceback (most recent call last):
  File "/Users/tiago/working_PAPERS/SAXS_oligo_Kd/plotly_dash_tests/saxs_binding_equilibria_app_v3/scripts/callbacks_analysis.py", line 192, in run_analysis
    line=dict(color=concentration_colors[concentration])  # Use the same color as for the fits
KeyError: nan
2024-09-18 12:13:59,297 - saxs_analysis - WARNING - Fit file /Users/tiago/working_PAPERS/SAXS_oligo_Kd/plotly_dash_tests/saxs_binding_equilibria_app_v3/data/fit_36.0_366.5241237079626.fit does not exist.
2024-09-18 12:14:00,481 - saxs_analysis - WARNING - Fit file /Users/tiago/working_PAPERS/SAXS_oligo_Kd/plotly_dash_tests/saxs_binding_equilibria_app_v3/data/fit_138.0_366.5241237079626.fit does not exist.
2024-09-18 12:14:50,636 - saxs_analysis - WARNING - Fit file /Users/tiago/working_PAPERS/SAXS_oligo_Kd/plotly_dash_tests/saxs_binding_equilibria_app_v3/data/fit_30.0_228.54638641349885.fit does not exist.
2024-09-18 12:14:51,785 - saxs_analysis - WARNING - Fit file /Users/tiago/working_PAPERS/SAXS_oligo_Kd/plotly_dash_tests/saxs_binding_equilibria_app_v3/data/fit_136.0_366.5241237079626.fit does not exist.
2024-09-18 12:15:54,892 - saxs_analysis - WARNING - Fit file /Users/tiago/working_PAPERS/SAXS_oligo_Kd/plotly_dash_tests/saxs_binding_equilibria_app_v3/data/fit_30.0_228.54638641349885.fit does not exist.
2024-09-18 12:15:56,080 - saxs_analysis - WARNING - Fit file /Users/tiago/working_PAPERS/SAXS_oligo_Kd/plotly_dash_tests/saxs_binding_equilibria_app_v3/data/fit_136.0_366.5241237079626.fit does not exist.
2024-09-18 12:16:30,465 - saxs_analysis - WARNING - Fit file /Users/tiago/working_PAPERS/SAXS_oligo_Kd/plotly_dash_tests/saxs_binding_equilibria_app_v3/data/fit_36.0_366.5241237079626.fit does not exist.
2024-09-18 12:16:31,633 - saxs_analysis - WARNING - Fit file /Users/tiago/working_PAPERS/SAXS_oligo_Kd/plotly_dash_tests/saxs_binding_equilibria_app_v3/data/fit_138.0_366.5241237079626.fit does not exist.
2024-09-18 12:16:34,944 - saxs_analysis - WARNING - Fit file /Users/tiago/working_PAPERS/SAXS_oligo_Kd/plotly_dash_tests/saxs_binding_equilibria_app_v3/data/fit_36.0_366.5241237079626.fit does not exist.
2024-09-18 12:16:36,154 - saxs_analysis - WARNING - Fit file /Users/tiago/working_PAPERS/SAXS_oligo_Kd/plotly_dash_tests/saxs_binding_equilibria_app_v3/data/fit_138.0_366.5241237079626.fit does not exist.
2024-09-18 12:39:09,758 - saxs_analysis - WARNING - Fit file /Users/tiago/working_PAPERS/SAXS_oligo_Kd/plotly_dash_tests/saxs_binding_equilibria_app_v3/data/fit_36.0_366.5241237079626.fit does not exist.
2024-09-18 12:39:10,977 - saxs_analysis - WARNING - Fit file /Users/tiago/working_PAPERS/SAXS_oligo_Kd/plotly_dash_tests/saxs_binding_equilibria_app_v3/data/fit_138.0_366.5241237079626.fit does not exist.
2024-09-18 12:40:46,007 - saxs_analysis - WARNING - Fit file /Users/tiago/working_PAPERS/SAXS_oligo_Kd/plotly_dash_tests/saxs_binding_equilibria_app_v3/data/fit_nan_21.54434690031882.fit does not exist.
2024-09-18 12:40:46,015 - saxs_analysis - ERROR - An error occurred during analysis: nan
Traceback (most recent call last):
  File "/Users/tiago/working_PAPERS/SAXS_oligo_Kd/plotly_dash_tests/saxs_binding_equilibria_app_v3/scripts/callbacks_analysis.py", line 193, in run_analysis
    line=dict(color=concentration_colors[concentration])  # Use the same color as for the fits
KeyError: nan
2024-09-18 12:41:54,223 - saxs_analysis - ERROR - An error occurred during analysis: Receptor concentration is required for the ProteinBindingCalculation model
Traceback (most recent call last):
  File "/Users/tiago/working_PAPERS/SAXS_oligo_Kd/plotly_dash_tests/saxs_binding_equilibria_app_v3/scripts/callbacks_analysis.py", line 72, in run_analysis
    raise ValueError("Receptor concentration is required for the ProteinBindingCalculation model")
ValueError: Receptor concentration is required for the ProteinBindingCalculation model
2024-09-18 12:42:10,071 - saxs_analysis - WARNING - Fit file /Users/tiago/working_PAPERS/SAXS_oligo_Kd/plotly_dash_tests/saxs_binding_equilibria_app_v3/data/fit_nan_21.54434690031882.fit does not exist.
2024-09-18 12:42:10,071 - saxs_analysis - ERROR - KeyError: 'contents' in item 1
2024-09-18 12:42:10,079 - saxs_analysis - ERROR - An error occurred during analysis: nan
Traceback (most recent call last):
  File "/Users/tiago/working_PAPERS/SAXS_oligo_Kd/plotly_dash_tests/saxs_binding_equilibria_app_v3/scripts/callbacks_analysis.py", line 193, in run_analysis
    line=dict(color=concentration_colors[concentration])  # Use the same color as for the fits
KeyError: nan
2024-09-18 12:46:38,266 - saxs_analysis - ERROR - KeyError: 'contents' in item 0
2024-09-18 12:46:38,266 - saxs_analysis - ERROR - KeyError: 'contents' in item 1
2024-09-18 12:47:09,831 - saxs_analysis - WARNING - Fit file /Users/tiago/working_PAPERS/SAXS_oligo_Kd/plotly_dash_tests/saxs_binding_equilibria_app_v3/data/fit_30.0_21.54434690031882.fit does not exist.
2024-09-18 12:47:09,831 - saxs_analysis - ERROR - KeyError: 'contents' in item 1
2024-09-18 12:48:40,953 - saxs_analysis - WARNING - Fit file /Users/tiago/working_PAPERS/SAXS_oligo_Kd/plotly_dash_tests/saxs_binding_equilibria_app_v3/data/fit_30.0_21.54434690031882.fit does not exist.
2024-09-18 12:48:40,953 - saxs_analysis - ERROR - KeyError: 'contents' in item 1
2024-09-18 12:54:13,107 - saxs_analysis - WARNING - Fit file /Users/tiago/working_PAPERS/SAXS_oligo_Kd/plotly_dash_tests/saxs_binding_equilibria_app_v3/data/fit_30.0_21.54434690031882.fit does not exist.
2024-09-18 12:54:13,107 - saxs_analysis - ERROR - KeyError: 'contents' in item 1
2024-09-18 13:07:45,052 - saxs_analysis - WARNING - Fit file /Users/tiago/working_PAPERS/SAXS_oligo_Kd/plotly_dash_tests/saxs_binding_equilibria_app_v3/data/fit_36.0_366.5241237079626.fit does not exist.
2024-09-18 13:07:45,052 - saxs_analysis - ERROR - KeyError: 'contents' in item 1
2024-09-18 13:10:17,896 - saxs_analysis - WARNING - Fit file /Users/tiago/working_PAPERS/SAXS_oligo_Kd/plotly_dash_tests/saxs_binding_equilibria_app_v3/data/fit_30_21.54434690031882.fit does not exist.
2024-09-18 13:11:59,306 - saxs_analysis - ERROR - KeyError: 'contents' in item 1
2024-09-18 13:12:41,830 - saxs_analysis - ERROR - KeyError: 'contents' in item 1
2024-09-18 13:13:41,325 - saxs_analysis - ERROR - Error in ProteinBindingCalculation: operands could not be broadcast together with shapes (301,2) (1645,2) (301,2) 
2024-09-18 13:13:41,325 - saxs_analysis - ERROR - An error occurred during analysis: operands could not be broadcast together with shapes (301,2) (1645,2) (301,2) 
Traceback (most recent call last):
  File "/Users/tiago/working_PAPERS/SAXS_oligo_Kd/plotly_dash_tests/saxs_binding_equilibria_app_v3/scripts/callbacks_analysis.py", line 77, in run_analysis
    chi_squared_df = model.calculate(
  File "/Users/tiago/working_PAPERS/SAXS_oligo_Kd/plotly_dash_tests/saxs_binding_equilibria_app_v3/models/protein_binding.py", line 10, in calculate
    return ProteinBindingCalculation.calculate(exp_saxs, theoretical_saxs_files, receptor_concentration, ligand_concentration, n)
  File "/Users/tiago/working_PAPERS/SAXS_oligo_Kd/plotly_dash_tests/saxs_binding_equilibria_app_v3/models/calculations.py", line 151, in calculate
    theoretical_saxs += PCNA_fracs[j] * np.loadtxt(theoretical_saxs_files[j], usecols=(0, 1))
ValueError: operands could not be broadcast together with shapes (301,2) (1645,2) (301,2) 
2024-09-18 13:14:13,693 - saxs_analysis - ERROR - KeyError: 'contents' in item 1
2024-09-18 16:39:58,086 - saxs_analysis - ERROR - An error occurred during analysis: calculate() missing 1 required positional argument: 'kd_range'
Traceback (most recent call last):
  File "/Users/tiago/working_PAPERS/SAXS_oligo_Kd/plotly_dash_tests/saxs_binding_equilibria_app_v3/scripts/callbacks_analysis.py", line 77, in run_analysis
    chi_squared_df = model.calculate(
TypeError: calculate() missing 1 required positional argument: 'kd_range'
2024-09-19 15:43:41,381 - saxs_analysis - ERROR - An error occurred during analysis: name 'upload_directory' is not defined
Traceback (most recent call last):
  File "/Users/tiago/working_PAPERS/SAXS_oligo_Kd/plotly_dash_tests/saxs_binding_equilibria_app_v3/scripts/callbacks_analysis.py", line 206, in run_analysis
    results, concentration_colors = process_data(selected_model, n_value, upload_container, theoretical_saxs_uploads, kd_range, receptor_concentration)
  File "/Users/tiago/working_PAPERS/SAXS_oligo_Kd/plotly_dash_tests/saxs_binding_equilibria_app_v3/scripts/callbacks_analysis.py", line 36, in process_data
    exp_file_path = save_file(exp_filename, exp_saxs, upload_directory)
NameError: name 'upload_directory' is not defined
2024-09-19 15:45:10,045 - saxs_analysis - ERROR - An error occurred during analysis: 'contents'
Traceback (most recent call last):
  File "/Users/tiago/working_PAPERS/SAXS_oligo_Kd/plotly_dash_tests/saxs_binding_equilibria_app_v3/scripts/callbacks_analysis.py", line 59, in run_analysis
    mon_saxs = theoretical_saxs_uploads[0]['props']['contents']
KeyError: 'contents'
2024-09-19 15:46:37,705 - saxs_analysis - ERROR - KeyError: 'contents' in item 0
2024-09-19 15:46:37,708 - saxs_analysis - ERROR - An error occurred during analysis: calculate() missing 1 required positional argument: 'kd_range'
Traceback (most recent call last):
  File "/Users/tiago/working_PAPERS/SAXS_oligo_Kd/plotly_dash_tests/saxs_binding_equilibria_app_v3/scripts/callbacks_analysis.py", line 77, in run_analysis
    chi_squared_df = model.calculate(
TypeError: calculate() missing 1 required positional argument: 'kd_range'
2024-09-19 16:13:36,483 - saxs_analysis - ERROR - An error occurred: list index out of range
Traceback (most recent call last):
  File "/Users/tiago/working_PAPERS/SAXS_oligo_Kd/plotly_dash_tests/saxs_binding_equilibria_app_v3/scripts/error_handling.py", line 41, in wrapper
    return func(*args, **kwargs)
  File "/Users/tiago/working_PAPERS/SAXS_oligo_Kd/plotly_dash_tests/saxs_binding_equilibria_app_v3/scripts/callbacks_analysis.py", line 170, in run_analysis
    n_value = n_input_children[1]['props']['value']
IndexError: list index out of range
2024-09-19 16:43:40,762 - saxs_analysis - ERROR - KeyError: 'contents' in item 0
2024-09-19 16:43:52,730 - saxs_analysis - ERROR - KeyError: 'contents' in item 0
2024-09-19 16:48:53,688 - saxs_analysis - ERROR - Error during analysis
Traceback (most recent call last):
  File "/Users/tiago/working_PAPERS/SAXS_oligo_Kd/plotly_dash_tests/saxs_binding_equilibria_app_v3/scripts/callbacks_analysis.py", line 201, in run_analysis
    results, concentration_colors = process_saxs_data(selected_model, n_value, upload_container, theoretical_saxs_uploads, kd_range, receptor_concentration, upload_directory)
  File "/Users/tiago/working_PAPERS/SAXS_oligo_Kd/plotly_dash_tests/saxs_binding_equilibria_app_v3/scripts/callbacks_analysis.py", line 61, in process_saxs_data
    chi_squared_df = calculate_chi_squared(model, selected_model, exp_file_path, theoretical_saxs_uploads,
  File "/Users/tiago/working_PAPERS/SAXS_oligo_Kd/plotly_dash_tests/saxs_binding_equilibria_app_v3/scripts/callbacks_analysis.py", line 69, in calculate_chi_squared
    mon_saxs = theoretical_saxs_uploads[0]['props']['contents']
KeyError: 'contents'
2024-09-19 16:48:56,670 - saxs_analysis - ERROR - Error during analysis
Traceback (most recent call last):
  File "/Users/tiago/working_PAPERS/SAXS_oligo_Kd/plotly_dash_tests/saxs_binding_equilibria_app_v3/scripts/callbacks_analysis.py", line 201, in run_analysis
    results, concentration_colors = process_saxs_data(selected_model, n_value, upload_container, theoretical_saxs_uploads, kd_range, receptor_concentration, upload_directory)
  File "/Users/tiago/working_PAPERS/SAXS_oligo_Kd/plotly_dash_tests/saxs_binding_equilibria_app_v3/scripts/callbacks_analysis.py", line 61, in process_saxs_data
    chi_squared_df = calculate_chi_squared(model, selected_model, exp_file_path, theoretical_saxs_uploads,
  File "/Users/tiago/working_PAPERS/SAXS_oligo_Kd/plotly_dash_tests/saxs_binding_equilibria_app_v3/scripts/callbacks_analysis.py", line 69, in calculate_chi_squared
    mon_saxs = theoretical_saxs_uploads[0]['props']['contents']
KeyError: 'contents'
2024-09-19 16:49:04,110 - saxs_analysis - ERROR - Error during analysis
Traceback (most recent call last):
  File "/Users/tiago/working_PAPERS/SAXS_oligo_Kd/plotly_dash_tests/saxs_binding_equilibria_app_v3/scripts/callbacks_analysis.py", line 201, in run_analysis
    results, concentration_colors = process_saxs_data(selected_model, n_value, upload_container, theoretical_saxs_uploads, kd_range, receptor_concentration, upload_directory)
  File "/Users/tiago/working_PAPERS/SAXS_oligo_Kd/plotly_dash_tests/saxs_binding_equilibria_app_v3/scripts/callbacks_analysis.py", line 61, in process_saxs_data
    chi_squared_df = calculate_chi_squared(model, selected_model, exp_file_path, theoretical_saxs_uploads,
  File "/Users/tiago/working_PAPERS/SAXS_oligo_Kd/plotly_dash_tests/saxs_binding_equilibria_app_v3/scripts/callbacks_analysis.py", line 70, in calculate_chi_squared
    dim_saxs = theoretical_saxs_uploads[1]['props']['contents']
KeyError: 'contents'
2024-09-19 16:55:54,688 - saxs_analysis - ERROR - Missing required input: 'filename'
2024-09-19 16:56:18,767 - saxs_analysis - ERROR - Missing required input: 'filename'
2024-09-20 16:38:49,746 - saxs_analysis - ERROR - An unexpected error occurred: name 'dash' is not defined
Traceback (most recent call last):
  File "/Users/tiago/working_PAPERS/SAXS_oligo_Kd/plotly_dash_tests/saxs_binding_equilibria_app_v3/scripts/error_handling.py", line 41, in wrapper
    return func(*args, **kwargs)
  File "/Users/tiago/working_PAPERS/SAXS_oligo_Kd/plotly_dash_tests/saxs_binding_equilibria_app_v3/scripts/callbacks_analysis.py", line 212, in run_analysis
    ctx = dash.callback_context
NameError: name 'dash' is not defined
2024-09-20 16:39:57,527 - saxs_analysis - ERROR - An unexpected error occurred: name 'dash' is not defined
Traceback (most recent call last):
  File "/Users/tiago/working_PAPERS/SAXS_oligo_Kd/plotly_dash_tests/saxs_binding_equilibria_app_v3/scripts/error_handling.py", line 41, in wrapper
    return func(*args, **kwargs)
  File "/Users/tiago/working_PAPERS/SAXS_oligo_Kd/plotly_dash_tests/saxs_binding_equilibria_app_v3/scripts/callbacks_analysis.py", line 212, in run_analysis
    ctx = dash.callback_context
NameError: name 'dash' is not defined
2024-09-20 16:40:09,309 - saxs_analysis - ERROR - An unexpected error occurred: name 'dash' is not defined
Traceback (most recent call last):
  File "/Users/tiago/working_PAPERS/SAXS_oligo_Kd/plotly_dash_tests/saxs_binding_equilibria_app_v3/scripts/error_handling.py", line 41, in wrapper
    return func(*args, **kwargs)
  File "/Users/tiago/working_PAPERS/SAXS_oligo_Kd/plotly_dash_tests/saxs_binding_equilibria_app_v3/scripts/callbacks_analysis.py", line 212, in run_analysis
    ctx = dash.callback_context
NameError: name 'dash' is not defined
2024-09-20 16:41:39,974 - saxs_analysis - ERROR - Error during analysis
Traceback (most recent call last):
  File "/Users/tiago/working_PAPERS/SAXS_oligo_Kd/plotly_dash_tests/saxs_binding_equilibria_app_v3/scripts/callbacks_analysis.py", line 237, in run_analysis
    fraction_plot = create_fraction_plot(best_kd, n_value, concentration_range)
  File "/Users/tiago/working_PAPERS/SAXS_oligo_Kd/plotly_dash_tests/saxs_binding_equilibria_app_v3/scripts/callbacks_analysis.py", line 177, in create_fraction_plot
    fractions = MonomerOligomerCalculation.calculate_fractions(kd, concentration_range, n_value)
NameError: name 'MonomerOligomerCalculation' is not defined
2024-09-20 16:46:48,697 - saxs_analysis - ERROR - Error during analysis
Traceback (most recent call last):
  File "/Users/tiago/working_PAPERS/SAXS_oligo_Kd/plotly_dash_tests/saxs_binding_equilibria_app_v3/scripts/callbacks_analysis.py", line 239, in run_analysis
    fraction_plot = create_fraction_plot(best_kd, n_value, concentration_range)
  File "/Users/tiago/working_PAPERS/SAXS_oligo_Kd/plotly_dash_tests/saxs_binding_equilibria_app_v3/scripts/callbacks_analysis.py", line 186, in create_fraction_plot
    fig.update_layout(
  File "/Users/tiago/opt/anaconda3/lib/python3.9/site-packages/plotly/graph_objs/_figure.py", line 775, in update_layout
    return super(Figure, self).update_layout(dict1, overwrite, **kwargs)
  File "/Users/tiago/opt/anaconda3/lib/python3.9/site-packages/plotly/basedatatypes.py", line 1393, in update_layout
    self.layout.update(dict1, overwrite=overwrite, **kwargs)
  File "/Users/tiago/opt/anaconda3/lib/python3.9/site-packages/plotly/basedatatypes.py", line 5113, in update
    BaseFigure._perform_update(self, kwargs, overwrite=overwrite)
  File "/Users/tiago/opt/anaconda3/lib/python3.9/site-packages/plotly/basedatatypes.py", line 3876, in _perform_update
    raise err
ValueError: Invalid property specified for object of type plotly.graph_objs.layout.XAxis: 'typ'

Did you mean "type"?

    Valid properties:
        anchor
            If set to an opposite-letter axis id (e.g. `x2`, `y`),
            this axis is bound to the corresponding opposite-letter
            axis. If set to "free", this axis' position is
            determined by `position`.
        automargin
            Determines whether long tick labels automatically grow
            the figure margins.
        autorange
            Determines whether or not the range of this axis is
            computed in relation to the input data. See `rangemode`
            for more info. If `range` is provided, then `autorange`
            is set to False.
        autotypenumbers
            Using "strict" a numeric string in trace data is not
            converted to a number. Using *convert types* a numeric
            string in trace data may be treated as a number during
            automatic axis `type` detection. Defaults to
            layout.autotypenumbers.
        calendar
            Sets the calendar system to use for `range` and `tick0`
            if this is a date axis. This does not set the calendar
            for interpreting data on this axis, that's specified in
            the trace or via the global `layout.calendar`
        categoryarray
            Sets the order in which categories on this axis appear.
            Only has an effect if `categoryorder` is set to
            "array". Used with `categoryorder`.
        categoryarraysrc
            Sets the source reference on Chart Studio Cloud for
            `categoryarray`.
        categoryorder
            Specifies the ordering logic for the case of
            categorical variables. By default, plotly uses "trace",
            which specifies the order that is present in the data
            supplied. Set `categoryorder` to *category ascending*
            or *category descending* if order should be determined
            by the alphanumerical order of the category names. Set
            `categoryorder` to "array" to derive the ordering from
            the attribute `categoryarray`. If a category is not
            found in the `categoryarray` array, the sorting
            behavior for that attribute will be identical to the
            "trace" mode. The unspecified categories will follow
            the categories in `categoryarray`. Set `categoryorder`
            to *total ascending* or *total descending* if order
            should be determined by the numerical order of the
            values. Similarly, the order can be determined by the
            min, max, sum, mean or median of all the values.
        color
            Sets default for all colors associated with this axis
            all at once: line, font, tick, and grid colors. Grid
            color is lightened by blending this with the plot
            background Individual pieces can override this.
        constrain
            If this axis needs to be compressed (either due to its
            own `scaleanchor` and `scaleratio` or those of the
            other axis), determines how that happens: by increasing
            the "range", or by decreasing the "domain". Default is
            "domain" for axes containing image traces, "range"
            otherwise.
        constraintoward
            If this axis needs to be compressed (either due to its
            own `scaleanchor` and `scaleratio` or those of the
            other axis), determines which direction we push the
            originally specified plot area. Options are "left",
            "center" (default), and "right" for x axes, and "top",
            "middle" (default), and "bottom" for y axes.
        dividercolor
            Sets the color of the dividers Only has an effect on
            "multicategory" axes.
        dividerwidth
            Sets the width (in px) of the dividers Only has an
            effect on "multicategory" axes.
        domain
            Sets the domain of this axis (in plot fraction).
        dtick
            Sets the step in-between ticks on this axis. Use with
            `tick0`. Must be a positive number, or special strings
            available to "log" and "date" axes. If the axis `type`
            is "log", then ticks are set every 10^(n*dtick) where n
            is the tick number. For example, to set a tick mark at
            1, 10, 100, 1000, ... set dtick to 1. To set tick marks
            at 1, 100, 10000, ... set dtick to 2. To set tick marks
            at 1, 5, 25, 125, 625, 3125, ... set dtick to
            log_10(5), or 0.69897000433. "log" has several special
            values; "L<f>", where `f` is a positive number, gives
            ticks linearly spaced in value (but not position). For
            example `tick0` = 0.1, `dtick` = "L0.5" will put ticks
            at 0.1, 0.6, 1.1, 1.6 etc. To show powers of 10 plus
            small digits between, use "D1" (all digits) or "D2"
            (only 2 and 5). `tick0` is ignored for "D1" and "D2".
            If the axis `type` is "date", then you must convert the
            time to milliseconds. For example, to set the interval
            between ticks to one day, set `dtick` to 86400000.0.
            "date" also has special values "M<n>" gives ticks
            spaced by a number of months. `n` must be a positive
            integer. To set ticks on the 15th of every third month,
            set `tick0` to "2000-01-15" and `dtick` to "M3". To set
            ticks every 4 years, set `dtick` to "M48"
        exponentformat
            Determines a formatting rule for the tick exponents.
            For example, consider the number 1,000,000,000. If
            "none", it appears as 1,000,000,000. If "e", 1e+9. If
            "E", 1E+9. If "power", 1x10^9 (with 9 in a super
            script). If "SI", 1G. If "B", 1B.
        fixedrange
            Determines whether or not this axis is zoom-able. If
            true, then zoom is disabled.
        gridcolor
            Sets the color of the grid lines.
        griddash
            Sets the dash style of lines. Set to a dash type string
            ("solid", "dot", "dash", "longdash", "dashdot", or
            "longdashdot") or a dash length list in px (eg
            "5px,10px,2px,2px").
        gridwidth
            Sets the width (in px) of the grid lines.
        hoverformat
            Sets the hover text formatting rule using d3 formatting
            mini-languages which are very similar to those in
            Python. For numbers, see:
            https://github.com/d3/d3-format/tree/v1.4.5#d3-format.
            And for dates see: https://github.com/d3/d3-time-
            format/tree/v2.2.3#locale_format. We add two items to
            d3's date formatter: "%h" for half of the year as a
            decimal number as well as "%{n}f" for fractional
            seconds with n digits. For example, *2016-10-13
            09:15:23.456* with tickformat "%H~%M~%S.%2f" would
            display "09~15~23.46"
        labelalias
            Replacement text for specific tick or hover labels. For
            example using {US: 'USA', CA: 'Canada'} changes US to
            USA and CA to Canada. The labels we would have shown
            must match the keys exactly, after adding any
            tickprefix or ticksuffix. labelalias can be used with
            any axis type, and both keys (if needed) and values (if
            desired) can include html-like tags or MathJax.
        layer
            Sets the layer on which this axis is displayed. If
            *above traces*, this axis is displayed above all the
            subplot's traces If *below traces*, this axis is
            displayed below all the subplot's traces, but above the
            grid lines. Useful when used together with scatter-like
            traces with `cliponaxis` set to False to show markers
            and/or text nodes above this axis.
        linecolor
            Sets the axis line color.
        linewidth
            Sets the width (in px) of the axis line.
        matches
            If set to another axis id (e.g. `x2`, `y`), the range
            of this axis will match the range of the corresponding
            axis in data-coordinates space. Moreover, matching axes
            share auto-range values, category lists and histogram
            auto-bins. Note that setting axes simultaneously in
            both a `scaleanchor` and a `matches` constraint is
            currently forbidden. Moreover, note that matching axes
            must have the same `type`.
        minexponent
            Hide SI prefix for 10^n if |n| is below this number.
            This only has an effect when `tickformat` is "SI" or
            "B".
        minor
            :class:`plotly.graph_objects.layout.xaxis.Minor`
            instance or dict with compatible properties
        mirror
            Determines if the axis lines or/and ticks are mirrored
            to the opposite side of the plotting area. If True, the
            axis lines are mirrored. If "ticks", the axis lines and
            ticks are mirrored. If False, mirroring is disable. If
            "all", axis lines are mirrored on all shared-axes
            subplots. If "allticks", axis lines and ticks are
            mirrored on all shared-axes subplots.
        nticks
            Specifies the maximum number of ticks for the
            particular axis. The actual number of ticks will be
            chosen automatically to be less than or equal to
            `nticks`. Has an effect only if `tickmode` is set to
            "auto".
        overlaying
            If set a same-letter axis id, this axis is overlaid on
            top of the corresponding same-letter axis, with traces
            and axes visible for both axes. If False, this axis
            does not overlay any same-letter axes. In this case,
            for axes with overlapping domains only the highest-
            numbered axis will be visible.
        position
            Sets the position of this axis in the plotting space
            (in normalized coordinates). Only has an effect if
            `anchor` is set to "free".
        range
            Sets the range of this axis. If the axis `type` is
            "log", then you must take the log of your desired range
            (e.g. to set the range from 1 to 100, set the range
            from 0 to 2). If the axis `type` is "date", it should
            be date strings, like date data, though Date objects
            and unix milliseconds will be accepted and converted to
            strings. If the axis `type` is "category", it should be
            numbers, using the scale where each category is
            assigned a serial number from zero in the order it
            appears.
        rangebreaks
            A tuple of
            :class:`plotly.graph_objects.layout.xaxis.Rangebreak`
            instances or dicts with compatible properties
        rangebreakdefaults
            When used in a template (as
            layout.template.layout.xaxis.rangebreakdefaults), sets
            the default property values to use for elements of
            layout.xaxis.rangebreaks
        rangemode
            If "normal", the range is computed in relation to the
            extrema of the input data. If *tozero*`, the range
            extends to 0, regardless of the input data If
            "nonnegative", the range is non-negative, regardless of
            the input data. Applies only to linear axes.
        rangeselector
            :class:`plotly.graph_objects.layout.xaxis.Rangeselector
            ` instance or dict with compatible properties
        rangeslider
            :class:`plotly.graph_objects.layout.xaxis.Rangeslider`
            instance or dict with compatible properties
        scaleanchor
            If set to another axis id (e.g. `x2`, `y`), the range
            of this axis changes together with the range of the
            corresponding axis such that the scale of pixels per
            unit is in a constant ratio. Both axes are still
            zoomable, but when you zoom one, the other will zoom
            the same amount, keeping a fixed midpoint. `constrain`
            and `constraintoward` determine how we enforce the
            constraint. You can chain these, ie `yaxis:
            {scaleanchor: *x*}, xaxis2: {scaleanchor: *y*}` but you
            can only link axes of the same `type`. The linked axis
            can have the opposite letter (to constrain the aspect
            ratio) or the same letter (to match scales across
            subplots). Loops (`yaxis: {scaleanchor: *x*}, xaxis:
            {scaleanchor: *y*}` or longer) are redundant and the
            last constraint encountered will be ignored to avoid
            possible inconsistent constraints via `scaleratio`.
            Note that setting axes simultaneously in both a
            `scaleanchor` and a `matches` constraint is currently
            forbidden.
        scaleratio
            If this axis is linked to another by `scaleanchor`,
            this determines the pixel to unit scale ratio. For
            example, if this value is 10, then every unit on this
            axis spans 10 times the number of pixels as a unit on
            the linked axis. Use this for example to create an
            elevation profile where the vertical scale is
            exaggerated a fixed amount with respect to the
            horizontal.
        separatethousands
            If "true", even 4-digit integers are separated
        showdividers
            Determines whether or not a dividers are drawn between
            the category levels of this axis. Only has an effect on
            "multicategory" axes.
        showexponent
            If "all", all exponents are shown besides their
            significands. If "first", only the exponent of the
            first tick is shown. If "last", only the exponent of
            the last tick is shown. If "none", no exponents appear.
        showgrid
            Determines whether or not grid lines are drawn. If
            True, the grid lines are drawn at every tick mark.
        showline
            Determines whether or not a line bounding this axis is
            drawn.
        showspikes
            Determines whether or not spikes (aka droplines) are
            drawn for this axis. Note: This only takes affect when
            hovermode = closest
        showticklabels
            Determines whether or not the tick labels are drawn.
        showtickprefix
            If "all", all tick labels are displayed with a prefix.
            If "first", only the first tick is displayed with a
            prefix. If "last", only the last tick is displayed with
            a suffix. If "none", tick prefixes are hidden.
        showticksuffix
            Same as `showtickprefix` but for tick suffixes.
        side
            Determines whether a x (y) axis is positioned at the
            "bottom" ("left") or "top" ("right") of the plotting
            area.
        spikecolor
            Sets the spike color. If undefined, will use the series
            color
        spikedash
            Sets the dash style of lines. Set to a dash type string
            ("solid", "dot", "dash", "longdash", "dashdot", or
            "longdashdot") or a dash length list in px (eg
            "5px,10px,2px,2px").
        spikemode
            Determines the drawing mode for the spike line If
            "toaxis", the line is drawn from the data point to the
            axis the  series is plotted on. If "across", the line
            is drawn across the entire plot area, and supercedes
            "toaxis". If "marker", then a marker dot is drawn on
            the axis the series is plotted on
        spikesnap
            Determines whether spikelines are stuck to the cursor
            or to the closest datapoints.
        spikethickness
            Sets the width (in px) of the zero line.
        tick0
            Sets the placement of the first tick on this axis. Use
            with `dtick`. If the axis `type` is "log", then you
            must take the log of your starting tick (e.g. to set
            the starting tick to 100, set the `tick0` to 2) except
            when `dtick`=*L<f>* (see `dtick` for more info). If the
            axis `type` is "date", it should be a date string, like
            date data. If the axis `type` is "category", it should
            be a number, using the scale where each category is
            assigned a serial number from zero in the order it
            appears.
        tickangle
            Sets the angle of the tick labels with respect to the
            horizontal. For example, a `tickangle` of -90 draws the
            tick labels vertically.
        tickcolor
            Sets the tick color.
        tickfont
            Sets the tick font.
        tickformat
            Sets the tick label formatting rule using d3 formatting
            mini-languages which are very similar to those in
            Python. For numbers, see:
            https://github.com/d3/d3-format/tree/v1.4.5#d3-format.
            And for dates see: https://github.com/d3/d3-time-
            format/tree/v2.2.3#locale_format. We add two items to
            d3's date formatter: "%h" for half of the year as a
            decimal number as well as "%{n}f" for fractional
            seconds with n digits. For example, *2016-10-13
            09:15:23.456* with tickformat "%H~%M~%S.%2f" would
            display "09~15~23.46"
        tickformatstops
            A tuple of :class:`plotly.graph_objects.layout.xaxis.Ti
            ckformatstop` instances or dicts with compatible
            properties
        tickformatstopdefaults
            When used in a template (as
            layout.template.layout.xaxis.tickformatstopdefaults),
            sets the default property values to use for elements of
            layout.xaxis.tickformatstops
        ticklabelmode
            Determines where tick labels are drawn with respect to
            their corresponding ticks and grid lines. Only has an
            effect for axes of `type` "date" When set to "period",
            tick labels are drawn in the middle of the period
            between ticks.
        ticklabeloverflow
            Determines how we handle tick labels that would
            overflow either the graph div or the domain of the
            axis. The default value for inside tick labels is *hide
            past domain*. Otherwise on "category" and
            "multicategory" axes the default is "allow". In other
            cases the default is *hide past div*.
        ticklabelposition
            Determines where tick labels are drawn with respect to
            the axis Please note that top or bottom has no effect
            on x axes or when `ticklabelmode` is set to "period".
            Similarly left or right has no effect on y axes or when
            `ticklabelmode` is set to "period". Has no effect on
            "multicategory" axes or when `tickson` is set to
            "boundaries". When used on axes linked by `matches` or
            `scaleanchor`, no extra padding for inside labels would
            be added by autorange, so that the scales could match.
        ticklabelstep
            Sets the spacing between tick labels as compared to the
            spacing between ticks. A value of 1 (default) means
            each tick gets a label. A value of 2 means shows every
            2nd label. A larger value n means only every nth tick
            is labeled. `tick0` determines which labels are shown.
            Not implemented for axes with `type` "log" or
            "multicategory", or when `tickmode` is "array".
        ticklen
            Sets the tick length (in px).
        tickmode
            Sets the tick mode for this axis. If "auto", the number
            of ticks is set via `nticks`. If "linear", the
            placement of the ticks is determined by a starting
            position `tick0` and a tick step `dtick` ("linear" is
            the default value if `tick0` and `dtick` are provided).
            If "array", the placement of the ticks is set via
            `tickvals` and the tick text is `ticktext`. ("array" is
            the default value if `tickvals` is provided). If
            "sync", the number of ticks will sync with the
            overlayed axis set by `overlaying` property.
        tickprefix
            Sets a tick label prefix.
        ticks
            Determines whether ticks are drawn or not. If "", this
            axis' ticks are not drawn. If "outside" ("inside"),
            this axis' are drawn outside (inside) the axis lines.
        tickson
            Determines where ticks and grid lines are drawn with
            respect to their corresponding tick labels. Only has an
            effect for axes of `type` "category" or
            "multicategory". When set to "boundaries", ticks and
            grid lines are drawn half a category to the left/bottom
            of labels.
        ticksuffix
            Sets a tick label suffix.
        ticktext
            Sets the text displayed at the ticks position via
            `tickvals`. Only has an effect if `tickmode` is set to
            "array". Used with `tickvals`.
        ticktextsrc
            Sets the source reference on Chart Studio Cloud for
            `ticktext`.
        tickvals
            Sets the values at which ticks on this axis appear.
            Only has an effect if `tickmode` is set to "array".
            Used with `ticktext`.
        tickvalssrc
            Sets the source reference on Chart Studio Cloud for
            `tickvals`.
        tickwidth
            Sets the tick width (in px).
        title
            :class:`plotly.graph_objects.layout.xaxis.Title`
            instance or dict with compatible properties
        titlefont
            Deprecated: Please use layout.xaxis.title.font instead.
            Sets this axis' title font. Note that the title's font
            used to be customized by the now deprecated `titlefont`
            attribute.
        type
            Sets the axis type. By default, plotly attempts to
            determined the axis type by looking into the data of
            the traces that referenced the axis in question.
        uirevision
            Controls persistence of user-driven changes in axis
            `range`, `autorange`, and `title` if in `editable:
            true` configuration. Defaults to `layout.uirevision`.
        visible
            A single toggle to hide the axis while preserving
            interaction like dragging. Default is true when a
            cheater plot is present on the axis, otherwise false
        zeroline
            Determines whether or not a line is drawn at along the
            0 value of this axis. If True, the zero line is drawn
            on top of the grid lines.
        zerolinecolor
            Sets the line color of the zero line.
        zerolinewidth
            Sets the width (in px) of the zero line.
        
Did you mean "type"?

Bad property path:
xaxis_typ
      ^^^
2024-09-20 17:05:36,139 - saxs_analysis - ERROR - Error in MonomerOligomerCalculation: loop of ufunc does not support argument 0 of type float which has no callable log10 method
2024-09-20 17:05:36,139 - saxs_analysis - ERROR - Error during analysis
AttributeError: 'float' object has no attribute 'log10'

The above exception was the direct cause of the following exception:

Traceback (most recent call last):
  File "/Users/tiago/working_PAPERS/SAXS_oligo_Kd/plotly_dash_tests/saxs_binding_equilibria_app_v3/scripts/callbacks_analysis.py", line 243, in run_analysis
    results, concentration_colors = process_saxs_data(selected_model, n_value, upload_container, theoretical_saxs_uploads, kd_range, receptor_concentration, upload_directory)
  File "/Users/tiago/working_PAPERS/SAXS_oligo_Kd/plotly_dash_tests/saxs_binding_equilibria_app_v3/scripts/callbacks_analysis.py", line 64, in process_saxs_data
    chi_squared_df = calculate_chi_squared(model, selected_model, exp_file_path, theoretical_saxs_uploads,
  File "/Users/tiago/working_PAPERS/SAXS_oligo_Kd/plotly_dash_tests/saxs_binding_equilibria_app_v3/scripts/callbacks_analysis.py", line 76, in calculate_chi_squared
    return model.calculate(exp_file_path, mon_file_path, dim_file_path, ligand_concentration, n_value, kd_range)
  File "/Users/tiago/working_PAPERS/SAXS_oligo_Kd/plotly_dash_tests/saxs_binding_equilibria_app_v3/models/monomer_oligomer.py", line 7, in calculate
    return MonomerOligomerCalculation.calculate(exp_saxs, mon_avg_int, dim_avg_int, concentration, n, kd_range)
  File "/Users/tiago/working_PAPERS/SAXS_oligo_Kd/plotly_dash_tests/saxs_binding_equilibria_app_v3/models/calculations.py", line 38, in calculate
    Kd_values = np.geomspace(10**kd_range[0], 10**kd_range[1], num=KD_POINTS)
  File "/Users/tiago/opt/anaconda3/lib/python3.9/site-packages/numpy/core/function_base.py", line 445, in geomspace
    log_start = _nx.log10(start)
TypeError: loop of ufunc does not support argument 0 of type float which has no callable log10 method
2024-09-20 17:10:11,286 - saxs_analysis - ERROR - An unexpected error occurred: local variable 'concentration_range' referenced before assignment
Traceback (most recent call last):
  File "/Users/tiago/working_PAPERS/SAXS_oligo_Kd/plotly_dash_tests/saxs_binding_equilibria_app_v3/scripts/error_handling.py", line 41, in wrapper
    return func(*args, **kwargs)
  File "/Users/tiago/working_PAPERS/SAXS_oligo_Kd/plotly_dash_tests/saxs_binding_equilibria_app_v3/scripts/callbacks_analysis.py", line 263, in run_analysis
    fraction_plot = create_fraction_plot(selected_kd, n_value, concentration_range)
UnboundLocalError: local variable 'concentration_range' referenced before assignment
2024-09-20 17:10:13,967 - saxs_analysis - ERROR - An unexpected error occurred: local variable 'concentration_range' referenced before assignment
Traceback (most recent call last):
  File "/Users/tiago/working_PAPERS/SAXS_oligo_Kd/plotly_dash_tests/saxs_binding_equilibria_app_v3/scripts/error_handling.py", line 41, in wrapper
    return func(*args, **kwargs)
  File "/Users/tiago/working_PAPERS/SAXS_oligo_Kd/plotly_dash_tests/saxs_binding_equilibria_app_v3/scripts/callbacks_analysis.py", line 263, in run_analysis
    fraction_plot = create_fraction_plot(selected_kd, n_value, concentration_range)
UnboundLocalError: local variable 'concentration_range' referenced before assignment
2024-09-20 18:59:14,375 - saxs_analysis - ERROR - Error during analysis
Traceback (most recent call last):
  File "/Users/tiago/working_PAPERS/SAXS_oligo_Kd/plotly_dash_tests/saxs_binding_equilibria_app_v3/scripts/callbacks_analysis.py", line 273, in run_analysis
    fraction_plot = create_fraction_plot(best_kd, n_value, concentration_range, selected_model, receptor_concentration)
  File "/Users/tiago/working_PAPERS/SAXS_oligo_Kd/plotly_dash_tests/saxs_binding_equilibria_app_v3/scripts/callbacks_analysis.py", line 193, in create_fraction_plot
    fractions = ProteinBindingCalculation.calculate_fractions(kd, concentration_range, n_value, receptor_concentration)
  File "/Users/tiago/working_PAPERS/SAXS_oligo_Kd/plotly_dash_tests/saxs_binding_equilibria_app_v3/models/calculations.py", line 210, in calculate_fractions
    receptor_vals, ligand_free = ProteinBindingCalculation.solve_binding_system_generalized(
AttributeError: type object 'ProteinBindingCalculation' has no attribute 'solve_binding_system_generalized'
2024-09-23 13:24:38,808 - saxs_analysis - ERROR - Error during analysis
Traceback (most recent call last):
  File "/Users/tiago/working_PAPERS/SAXS_oligo_Kd/plotly_dash_tests/saxs_binding_equilibria_app_v3/scripts/callbacks_analysis.py", line 265, in run_analysis
    results, concentration_colors = process_saxs_data(selected_model, n_value, upload_container, theoretical_saxs_uploads, kd_range, receptor_concentration, upload_directory)
  File "/Users/tiago/working_PAPERS/SAXS_oligo_Kd/plotly_dash_tests/saxs_binding_equilibria_app_v3/scripts/callbacks_analysis.py", line 62, in process_saxs_data
    exp_file_path = save_file(exp_filename, exp_saxs, upload_directory)
NameError: name 'save_file' is not defined
2024-09-23 13:25:33,772 - saxs_analysis - ERROR - Error during analysis
Traceback (most recent call last):
  File "/Users/tiago/working_PAPERS/SAXS_oligo_Kd/plotly_dash_tests/saxs_binding_equilibria_app_v3/scripts/callbacks_analysis.py", line 265, in run_analysis
    results, concentration_colors = process_saxs_data(selected_model, n_value, upload_container, theoretical_saxs_uploads, kd_range, receptor_concentration, upload_directory)
  File "/Users/tiago/working_PAPERS/SAXS_oligo_Kd/plotly_dash_tests/saxs_binding_equilibria_app_v3/scripts/callbacks_analysis.py", line 62, in process_saxs_data
    exp_file_path = save_file(exp_filename, exp_saxs, upload_directory)
NameError: name 'save_file' is not defined
2024-09-23 13:26:22,963 - saxs_analysis - ERROR - Error during analysis
Traceback (most recent call last):
  File "/Users/tiago/working_PAPERS/SAXS_oligo_Kd/plotly_dash_tests/saxs_binding_equilibria_app_v3/scripts/callbacks_analysis.py", line 265, in run_analysis
    results, concentration_colors = process_saxs_data(selected_model, n_value, upload_container, theoretical_saxs_uploads, kd_range, receptor_concentration, upload_directory)
  File "/Users/tiago/working_PAPERS/SAXS_oligo_Kd/plotly_dash_tests/saxs_binding_equilibria_app_v3/scripts/callbacks_analysis.py", line 62, in process_saxs_data
    exp_file_path = save_file(exp_filename, exp_saxs, upload_directory)
NameError: name 'save_file' is not defined
2024-09-23 13:27:14,363 - saxs_analysis - ERROR - KeyError: 'contents' in item 0
2024-09-23 13:27:14,363 - saxs_analysis - ERROR - KeyError: 'contents' in item 1
2024-09-23 18:12:01,921 - saxs_analysis - ERROR - Error during analysis
Traceback (most recent call last):
  File "/Users/tiago/working_PAPERS/SAXS_oligo_Kd/plotly_dash_tests/saxs_binding_equilibria_app_v3/scripts/callbacks_analysis.py", line 136, in run_analysis
    saxs_fit_plots = create_saxs_fit_plots(results, concentration_colors, upload_directory)
  File "/Users/tiago/working_PAPERS/SAXS_oligo_Kd/plotly_dash_tests/saxs_binding_equilibria_app_v3/plotting.py", line 44, in create_saxs_fit_plots
    fit_filepath = os.path.join(upload_directory, fit_filename)
NameError: name 'os' is not defined
2024-09-23 18:13:17,394 - saxs_analysis - ERROR - Error during analysis
Traceback (most recent call last):
  File "/Users/tiago/working_PAPERS/SAXS_oligo_Kd/plotly_dash_tests/saxs_binding_equilibria_app_v3/scripts/callbacks_analysis.py", line 140, in run_analysis
    fraction_plot = create_fraction_plot(best_kd, n_value, concentration_range, selected_model, receptor_concentration)
  File "/Users/tiago/working_PAPERS/SAXS_oligo_Kd/plotly_dash_tests/saxs_binding_equilibria_app_v3/plotting.py", line 107, in create_fraction_plot
    fractions = MonomerOligomerCalculation.calculate_fractions(kd, concentration_range, n_value)
NameError: name 'MonomerOligomerCalculation' is not defined
2024-09-24 11:10:13,826 - saxs_analysis - ERROR - Error during analysis
Traceback (most recent call last):
  File "/Users/tiago/working_PAPERS/SAXS_oligo_Kd/plotly_dash_tests/saxs_binding_equilibria_app_v3/scripts/callbacks_analysis.py", line 128, in run_analysis
    results, concentration_colors = process_saxs_data(selected_model, n_value, upload_container, theoretical_saxs_uploads, kd_range, receptor_concentration, upload_directory)
  File "/Users/tiago/working_PAPERS/SAXS_oligo_Kd/plotly_dash_tests/saxs_binding_equilibria_app_v3/scripts/callbacks_analysis.py", line 64, in process_saxs_data
    chi_squared_df = calculate_chi_squared(model, selected_model, exp_file_path, theoretical_saxs_uploads,
  File "/Users/tiago/working_PAPERS/SAXS_oligo_Kd/plotly_dash_tests/saxs_binding_equilibria_app_v3/scripts/callbacks_analysis.py", line 80, in calculate_chi_squared
    theoretical_files = [save_file(f"theo_saxs_{j+1}.dat", upload['props']['contents'], upload_directory)
  File "/Users/tiago/working_PAPERS/SAXS_oligo_Kd/plotly_dash_tests/saxs_binding_equilibria_app_v3/scripts/callbacks_analysis.py", line 80, in <listcomp>
    theoretical_files = [save_file(f"theo_saxs_{j+1}.dat", upload['props']['contents'], upload_directory)
KeyError: 'contents'
2024-09-24 11:10:50,983 - saxs_analysis - ERROR - Error during analysis
Traceback (most recent call last):
  File "/Users/tiago/working_PAPERS/SAXS_oligo_Kd/plotly_dash_tests/saxs_binding_equilibria_app_v3/scripts/callbacks_analysis.py", line 128, in run_analysis
    results, concentration_colors = process_saxs_data(selected_model, n_value, upload_container, theoretical_saxs_uploads, kd_range, receptor_concentration, upload_directory)
  File "/Users/tiago/working_PAPERS/SAXS_oligo_Kd/plotly_dash_tests/saxs_binding_equilibria_app_v3/scripts/callbacks_analysis.py", line 64, in process_saxs_data
    chi_squared_df = calculate_chi_squared(model, selected_model, exp_file_path, theoretical_saxs_uploads,
  File "/Users/tiago/working_PAPERS/SAXS_oligo_Kd/plotly_dash_tests/saxs_binding_equilibria_app_v3/scripts/callbacks_analysis.py", line 73, in calculate_chi_squared
    dim_saxs = theoretical_saxs_uploads[1]['props']['contents']
KeyError: 'contents'
2024-09-24 12:22:25,551 - saxs_analysis - ERROR - Error during analysis
Traceback (most recent call last):
  File "/Users/tiago/working_PAPERS/SAXS_oligo_Kd/plotly_dash_tests/saxs_binding_equilibria_app_v3/scripts/callbacks_analysis.py", line 117, in run_analysis
    results, concentration_colors = process_saxs_data(selected_model, n_value, upload_container, theoretical_saxs_uploads, kd_range, kd_points, receptor_concentration, upload_directory)
  File "/Users/tiago/working_PAPERS/SAXS_oligo_Kd/plotly_dash_tests/saxs_binding_equilibria_app_v3/scripts/callbacks_analysis.py", line 59, in process_saxs_data
    chi_squared_df = calculate_chi_squared(model, selected_model, exp_file_path, theoretical_saxs_uploads,
  File "/Users/tiago/working_PAPERS/SAXS_oligo_Kd/plotly_dash_tests/saxs_binding_equilibria_app_v3/scripts/callbacks_analysis.py", line 71, in calculate_chi_squared
    return model.calculate(exp_file_path, mon_file_path, dim_file_path, ligand_concentration, n_value, kd_range, kd_points)
TypeError: calculate() takes 7 positional arguments but 8 were given
2024-09-24 12:34:38,281 - saxs_analysis - ERROR - Error during analysis
Traceback (most recent call last):
  File "/Users/tiago/working_PAPERS/SAXS_oligo_Kd/plotly_dash_tests/saxs_binding_equilibria_app_v3/scripts/callbacks_analysis.py", line 119, in run_analysis
    chi_squared_plot = create_chi_squared_plot(results, concentration_colors)
  File "/Users/tiago/working_PAPERS/SAXS_oligo_Kd/plotly_dash_tests/saxs_binding_equilibria_app_v3/plotting.py", line 13, in create_chi_squared_plot
    chi_squared_values = pd.concat(results)
  File "/Users/tiago/opt/anaconda3/lib/python3.9/site-packages/pandas/util/_decorators.py", line 331, in wrapper
    return func(*args, **kwargs)
  File "/Users/tiago/opt/anaconda3/lib/python3.9/site-packages/pandas/core/reshape/concat.py", line 368, in concat
    op = _Concatenator(
  File "/Users/tiago/opt/anaconda3/lib/python3.9/site-packages/pandas/core/reshape/concat.py", line 448, in __init__
    raise ValueError("All objects passed were None")
ValueError: All objects passed were None
2024-09-24 12:34:57,167 - saxs_analysis - ERROR - Error during analysis
Traceback (most recent call last):
  File "/Users/tiago/working_PAPERS/SAXS_oligo_Kd/plotly_dash_tests/saxs_binding_equilibria_app_v3/scripts/callbacks_analysis.py", line 119, in run_analysis
    chi_squared_plot = create_chi_squared_plot(results, concentration_colors)
  File "/Users/tiago/working_PAPERS/SAXS_oligo_Kd/plotly_dash_tests/saxs_binding_equilibria_app_v3/plotting.py", line 13, in create_chi_squared_plot
    chi_squared_values = pd.concat(results)
  File "/Users/tiago/opt/anaconda3/lib/python3.9/site-packages/pandas/util/_decorators.py", line 331, in wrapper
    return func(*args, **kwargs)
  File "/Users/tiago/opt/anaconda3/lib/python3.9/site-packages/pandas/core/reshape/concat.py", line 368, in concat
    op = _Concatenator(
  File "/Users/tiago/opt/anaconda3/lib/python3.9/site-packages/pandas/core/reshape/concat.py", line 448, in __init__
    raise ValueError("All objects passed were None")
ValueError: All objects passed were None
2024-09-24 12:35:26,040 - saxs_analysis - ERROR - Error during analysis
Traceback (most recent call last):
  File "/Users/tiago/working_PAPERS/SAXS_oligo_Kd/plotly_dash_tests/saxs_binding_equilibria_app_v3/scripts/callbacks_analysis.py", line 119, in run_analysis
    chi_squared_plot = create_chi_squared_plot(results, concentration_colors)
  File "/Users/tiago/working_PAPERS/SAXS_oligo_Kd/plotly_dash_tests/saxs_binding_equilibria_app_v3/plotting.py", line 13, in create_chi_squared_plot
    chi_squared_values = pd.concat(results)
  File "/Users/tiago/opt/anaconda3/lib/python3.9/site-packages/pandas/util/_decorators.py", line 331, in wrapper
    return func(*args, **kwargs)
  File "/Users/tiago/opt/anaconda3/lib/python3.9/site-packages/pandas/core/reshape/concat.py", line 368, in concat
    op = _Concatenator(
  File "/Users/tiago/opt/anaconda3/lib/python3.9/site-packages/pandas/core/reshape/concat.py", line 448, in __init__
    raise ValueError("All objects passed were None")
ValueError: All objects passed were None
2024-09-24 12:48:01,334 - saxs_analysis - DEBUG - Callback triggered by: 
2024-09-24 12:48:01,334 - saxs_analysis - DEBUG - Parameters - n: 2, kd_min: 0.0001, kd_max: 10000, kd_points: 40, conc_min: 1, conc_max: 1000, conc_points: 50, receptor_concentration: None
2024-09-24 12:48:26,981 - saxs_analysis - DEBUG - Callback triggered by: run-analysis
2024-09-24 12:48:26,981 - saxs_analysis - DEBUG - Parameters - n: 2, kd_min: 0.0001, kd_max: 10000, kd_points: 40, conc_min: 1, conc_max: 1000, conc_points: 50, receptor_concentration: None
2024-09-24 12:48:26,981 - saxs_analysis - DEBUG - Processing SAXS file 1 with concentration 36 μM
2024-09-24 12:48:26,982 - saxs_analysis - DEBUG - Saved experimental SAXS file to /Users/tiago/working_PAPERS/SAXS_oligo_Kd/plotly_dash_tests/saxs_binding_equilibria_app_v3/data/exp_saxs_1.dat
2024-09-24 12:48:26,983 - saxs_analysis - WARNING - No valid data processed for SAXS file 1
2024-09-24 12:48:26,983 - saxs_analysis - DEBUG - Processing SAXS file 2 with concentration 138 μM
2024-09-24 12:48:26,983 - saxs_analysis - DEBUG - Saved experimental SAXS file to /Users/tiago/working_PAPERS/SAXS_oligo_Kd/plotly_dash_tests/saxs_binding_equilibria_app_v3/data/exp_saxs_2.dat
2024-09-24 12:48:26,984 - saxs_analysis - WARNING - No valid data processed for SAXS file 2
2024-09-24 12:48:26,984 - saxs_analysis - DEBUG - Number of valid results: 0
2024-09-24 12:48:26,984 - saxs_analysis - WARNING - No valid data processed.
2024-09-24 17:09:26,635 - saxs_analysis - ERROR - KeyError: 'contents' in item 2
2024-09-24 17:09:26,635 - saxs_analysis - ERROR - KeyError: 'contents' in item 3
2024-09-24 18:56:48,415 - saxs_analysis - ERROR - Error in run_analysis: 'contents'
Traceback (most recent call last):
  File "/Users/tiago/working_PAPERS/SAXS_oligo_Kd/plotly_dash_tests/saxs_binding_equilibria_app_v3/scripts/callbacks_analysis.py", line 126, in run_analysis
    results, concentration_colors = process_saxs_data(selected_model, n_value, upload_container, theoretical_saxs_uploads, kd_range, receptor_concentration, upload_directory)
  File "/Users/tiago/working_PAPERS/SAXS_oligo_Kd/plotly_dash_tests/saxs_binding_equilibria_app_v3/scripts/callbacks_analysis.py", line 65, in process_saxs_data
    chi_squared_df = calculate_chi_squared(model, selected_model, exp_file_path, theoretical_saxs_uploads,
  File "/Users/tiago/working_PAPERS/SAXS_oligo_Kd/plotly_dash_tests/saxs_binding_equilibria_app_v3/scripts/callbacks_analysis.py", line 81, in calculate_chi_squared
    theoretical_files = [save_file(f"theo_saxs_{j+1}.dat", upload['props']['contents'], upload_directory)
  File "/Users/tiago/working_PAPERS/SAXS_oligo_Kd/plotly_dash_tests/saxs_binding_equilibria_app_v3/scripts/callbacks_analysis.py", line 81, in <listcomp>
    theoretical_files = [save_file(f"theo_saxs_{j+1}.dat", upload['props']['contents'], upload_directory)
KeyError: 'contents'
2024-09-24 18:56:48,415 - saxs_analysis - ERROR - Error in run_analysis: 'contents'
Traceback (most recent call last):
  File "/Users/tiago/working_PAPERS/SAXS_oligo_Kd/plotly_dash_tests/saxs_binding_equilibria_app_v3/scripts/callbacks_analysis.py", line 126, in run_analysis
    results, concentration_colors = process_saxs_data(selected_model, n_value, upload_container, theoretical_saxs_uploads, kd_range, receptor_concentration, upload_directory)
  File "/Users/tiago/working_PAPERS/SAXS_oligo_Kd/plotly_dash_tests/saxs_binding_equilibria_app_v3/scripts/callbacks_analysis.py", line 65, in process_saxs_data
    chi_squared_df = calculate_chi_squared(model, selected_model, exp_file_path, theoretical_saxs_uploads,
  File "/Users/tiago/working_PAPERS/SAXS_oligo_Kd/plotly_dash_tests/saxs_binding_equilibria_app_v3/scripts/callbacks_analysis.py", line 81, in calculate_chi_squared
    theoretical_files = [save_file(f"theo_saxs_{j+1}.dat", upload['props']['contents'], upload_directory)
  File "/Users/tiago/working_PAPERS/SAXS_oligo_Kd/plotly_dash_tests/saxs_binding_equilibria_app_v3/scripts/callbacks_analysis.py", line 81, in <listcomp>
    theoretical_files = [save_file(f"theo_saxs_{j+1}.dat", upload['props']['contents'], upload_directory)
KeyError: 'contents'
2024-09-24 18:56:48,416 - saxs_analysis - ERROR - An error occurred: 'contents'
Traceback (most recent call last):
  File "/Users/tiago/working_PAPERS/SAXS_oligo_Kd/plotly_dash_tests/saxs_binding_equilibria_app_v3/scripts/error_handling.py", line 42, in wrapper
    return func(*args, **kwargs)
  File "/Users/tiago/working_PAPERS/SAXS_oligo_Kd/plotly_dash_tests/saxs_binding_equilibria_app_v3/scripts/callbacks_analysis.py", line 126, in run_analysis
    results, concentration_colors = process_saxs_data(selected_model, n_value, upload_container, theoretical_saxs_uploads, kd_range, receptor_concentration, upload_directory)
  File "/Users/tiago/working_PAPERS/SAXS_oligo_Kd/plotly_dash_tests/saxs_binding_equilibria_app_v3/scripts/callbacks_analysis.py", line 65, in process_saxs_data
    chi_squared_df = calculate_chi_squared(model, selected_model, exp_file_path, theoretical_saxs_uploads,
  File "/Users/tiago/working_PAPERS/SAXS_oligo_Kd/plotly_dash_tests/saxs_binding_equilibria_app_v3/scripts/callbacks_analysis.py", line 81, in calculate_chi_squared
    theoretical_files = [save_file(f"theo_saxs_{j+1}.dat", upload['props']['contents'], upload_directory)
  File "/Users/tiago/working_PAPERS/SAXS_oligo_Kd/plotly_dash_tests/saxs_binding_equilibria_app_v3/scripts/callbacks_analysis.py", line 81, in <listcomp>
    theoretical_files = [save_file(f"theo_saxs_{j+1}.dat", upload['props']['contents'], upload_directory)
KeyError: 'contents'
2024-09-24 18:56:48,416 - saxs_analysis - ERROR - An error occurred: 'contents'
Traceback (most recent call last):
  File "/Users/tiago/working_PAPERS/SAXS_oligo_Kd/plotly_dash_tests/saxs_binding_equilibria_app_v3/scripts/error_handling.py", line 42, in wrapper
    return func(*args, **kwargs)
  File "/Users/tiago/working_PAPERS/SAXS_oligo_Kd/plotly_dash_tests/saxs_binding_equilibria_app_v3/scripts/callbacks_analysis.py", line 126, in run_analysis
    results, concentration_colors = process_saxs_data(selected_model, n_value, upload_container, theoretical_saxs_uploads, kd_range, receptor_concentration, upload_directory)
  File "/Users/tiago/working_PAPERS/SAXS_oligo_Kd/plotly_dash_tests/saxs_binding_equilibria_app_v3/scripts/callbacks_analysis.py", line 65, in process_saxs_data
    chi_squared_df = calculate_chi_squared(model, selected_model, exp_file_path, theoretical_saxs_uploads,
  File "/Users/tiago/working_PAPERS/SAXS_oligo_Kd/plotly_dash_tests/saxs_binding_equilibria_app_v3/scripts/callbacks_analysis.py", line 81, in calculate_chi_squared
    theoretical_files = [save_file(f"theo_saxs_{j+1}.dat", upload['props']['contents'], upload_directory)
  File "/Users/tiago/working_PAPERS/SAXS_oligo_Kd/plotly_dash_tests/saxs_binding_equilibria_app_v3/scripts/callbacks_analysis.py", line 81, in <listcomp>
    theoretical_files = [save_file(f"theo_saxs_{j+1}.dat", upload['props']['contents'], upload_directory)
KeyError: 'contents'
2024-09-24 19:05:58,365 - saxs_analysis - ERROR - Error in MonomerOligomerCalculation: could not convert string '│' to float64 at row 0, column 1.
2024-09-24 19:05:58,365 - saxs_analysis - ERROR - Error in MonomerOligomerCalculation: could not convert string '│' to float64 at row 0, column 1.
2024-09-24 19:05:58,365 - saxs_analysis - ERROR - Error in run_analysis: could not convert string '│' to float64 at row 0, column 1.
ValueError: could not convert string to float: ''

The above exception was the direct cause of the following exception:

Traceback (most recent call last):
  File "/Users/tiago/working_PAPERS/SAXS_oligo_Kd/plotly_dash_tests/saxs_binding_equilibria_app_v3/scripts/callbacks_analysis.py", line 130, in run_analysis
    results, concentration_colors = process_saxs_data(selected_model, n_value, upload_container, theoretical_saxs_uploads, kd_range, receptor_concentration, upload_directory)
  File "/Users/tiago/working_PAPERS/SAXS_oligo_Kd/plotly_dash_tests/saxs_binding_equilibria_app_v3/scripts/callbacks_analysis.py", line 65, in process_saxs_data
    chi_squared_df = calculate_chi_squared(model, selected_model, exp_file_path, theoretical_saxs_uploads,
  File "/Users/tiago/working_PAPERS/SAXS_oligo_Kd/plotly_dash_tests/saxs_binding_equilibria_app_v3/scripts/callbacks_analysis.py", line 77, in calculate_chi_squared
    return model.calculate(exp_file_path, mon_file_path, dim_file_path, ligand_concentration, n_value, kd_range)
  File "/Users/tiago/working_PAPERS/SAXS_oligo_Kd/plotly_dash_tests/saxs_binding_equilibria_app_v3/models/monomer_oligomer.py", line 7, in calculate
    return MonomerOligomerCalculation.calculate(exp_saxs, mon_avg_int, dim_avg_int, concentration, n, kd_range)
  File "/Users/tiago/working_PAPERS/SAXS_oligo_Kd/plotly_dash_tests/saxs_binding_equilibria_app_v3/models/calculations.py", line 56, in calculate
    mon_avg_int = np.loadtxt(mon_avg_int, skiprows=1)
  File "/Users/tiago/opt/anaconda3/lib/python3.9/site-packages/numpy/lib/npyio.py", line 1373, in loadtxt
    arr = _read(fname, dtype=dtype, comment=comment, delimiter=delimiter,
  File "/Users/tiago/opt/anaconda3/lib/python3.9/site-packages/numpy/lib/npyio.py", line 1016, in _read
    arr = _load_from_filelike(
ValueError: could not convert string '│' to float64 at row 0, column 1.
2024-09-24 19:05:58,365 - saxs_analysis - ERROR - Error in run_analysis: could not convert string '│' to float64 at row 0, column 1.
ValueError: could not convert string to float: ''

The above exception was the direct cause of the following exception:

Traceback (most recent call last):
  File "/Users/tiago/working_PAPERS/SAXS_oligo_Kd/plotly_dash_tests/saxs_binding_equilibria_app_v3/scripts/callbacks_analysis.py", line 130, in run_analysis
    results, concentration_colors = process_saxs_data(selected_model, n_value, upload_container, theoretical_saxs_uploads, kd_range, receptor_concentration, upload_directory)
  File "/Users/tiago/working_PAPERS/SAXS_oligo_Kd/plotly_dash_tests/saxs_binding_equilibria_app_v3/scripts/callbacks_analysis.py", line 65, in process_saxs_data
    chi_squared_df = calculate_chi_squared(model, selected_model, exp_file_path, theoretical_saxs_uploads,
  File "/Users/tiago/working_PAPERS/SAXS_oligo_Kd/plotly_dash_tests/saxs_binding_equilibria_app_v3/scripts/callbacks_analysis.py", line 77, in calculate_chi_squared
    return model.calculate(exp_file_path, mon_file_path, dim_file_path, ligand_concentration, n_value, kd_range)
  File "/Users/tiago/working_PAPERS/SAXS_oligo_Kd/plotly_dash_tests/saxs_binding_equilibria_app_v3/models/monomer_oligomer.py", line 7, in calculate
    return MonomerOligomerCalculation.calculate(exp_saxs, mon_avg_int, dim_avg_int, concentration, n, kd_range)
  File "/Users/tiago/working_PAPERS/SAXS_oligo_Kd/plotly_dash_tests/saxs_binding_equilibria_app_v3/models/calculations.py", line 56, in calculate
    mon_avg_int = np.loadtxt(mon_avg_int, skiprows=1)
  File "/Users/tiago/opt/anaconda3/lib/python3.9/site-packages/numpy/lib/npyio.py", line 1373, in loadtxt
    arr = _read(fname, dtype=dtype, comment=comment, delimiter=delimiter,
  File "/Users/tiago/opt/anaconda3/lib/python3.9/site-packages/numpy/lib/npyio.py", line 1016, in _read
    arr = _load_from_filelike(
ValueError: could not convert string '│' to float64 at row 0, column 1.
2024-09-24 19:05:58,367 - saxs_analysis - ERROR - An error occurred: could not convert string '│' to float64 at row 0, column 1.
ValueError: could not convert string to float: ''

The above exception was the direct cause of the following exception:

Traceback (most recent call last):
  File "/Users/tiago/working_PAPERS/SAXS_oligo_Kd/plotly_dash_tests/saxs_binding_equilibria_app_v3/scripts/error_handling.py", line 42, in wrapper
    return func(*args, **kwargs)
  File "/Users/tiago/working_PAPERS/SAXS_oligo_Kd/plotly_dash_tests/saxs_binding_equilibria_app_v3/scripts/callbacks_analysis.py", line 130, in run_analysis
    results, concentration_colors = process_saxs_data(selected_model, n_value, upload_container, theoretical_saxs_uploads, kd_range, receptor_concentration, upload_directory)
  File "/Users/tiago/working_PAPERS/SAXS_oligo_Kd/plotly_dash_tests/saxs_binding_equilibria_app_v3/scripts/callbacks_analysis.py", line 65, in process_saxs_data
    chi_squared_df = calculate_chi_squared(model, selected_model, exp_file_path, theoretical_saxs_uploads,
  File "/Users/tiago/working_PAPERS/SAXS_oligo_Kd/plotly_dash_tests/saxs_binding_equilibria_app_v3/scripts/callbacks_analysis.py", line 77, in calculate_chi_squared
    return model.calculate(exp_file_path, mon_file_path, dim_file_path, ligand_concentration, n_value, kd_range)
  File "/Users/tiago/working_PAPERS/SAXS_oligo_Kd/plotly_dash_tests/saxs_binding_equilibria_app_v3/models/monomer_oligomer.py", line 7, in calculate
    return MonomerOligomerCalculation.calculate(exp_saxs, mon_avg_int, dim_avg_int, concentration, n, kd_range)
  File "/Users/tiago/working_PAPERS/SAXS_oligo_Kd/plotly_dash_tests/saxs_binding_equilibria_app_v3/models/calculations.py", line 56, in calculate
    mon_avg_int = np.loadtxt(mon_avg_int, skiprows=1)
  File "/Users/tiago/opt/anaconda3/lib/python3.9/site-packages/numpy/lib/npyio.py", line 1373, in loadtxt
    arr = _read(fname, dtype=dtype, comment=comment, delimiter=delimiter,
  File "/Users/tiago/opt/anaconda3/lib/python3.9/site-packages/numpy/lib/npyio.py", line 1016, in _read
    arr = _load_from_filelike(
ValueError: could not convert string '│' to float64 at row 0, column 1.
2024-09-24 19:05:58,367 - saxs_analysis - ERROR - An error occurred: could not convert string '│' to float64 at row 0, column 1.
ValueError: could not convert string to float: ''

The above exception was the direct cause of the following exception:

Traceback (most recent call last):
  File "/Users/tiago/working_PAPERS/SAXS_oligo_Kd/plotly_dash_tests/saxs_binding_equilibria_app_v3/scripts/error_handling.py", line 42, in wrapper
    return func(*args, **kwargs)
  File "/Users/tiago/working_PAPERS/SAXS_oligo_Kd/plotly_dash_tests/saxs_binding_equilibria_app_v3/scripts/callbacks_analysis.py", line 130, in run_analysis
    results, concentration_colors = process_saxs_data(selected_model, n_value, upload_container, theoretical_saxs_uploads, kd_range, receptor_concentration, upload_directory)
  File "/Users/tiago/working_PAPERS/SAXS_oligo_Kd/plotly_dash_tests/saxs_binding_equilibria_app_v3/scripts/callbacks_analysis.py", line 65, in process_saxs_data
    chi_squared_df = calculate_chi_squared(model, selected_model, exp_file_path, theoretical_saxs_uploads,
  File "/Users/tiago/working_PAPERS/SAXS_oligo_Kd/plotly_dash_tests/saxs_binding_equilibria_app_v3/scripts/callbacks_analysis.py", line 77, in calculate_chi_squared
    return model.calculate(exp_file_path, mon_file_path, dim_file_path, ligand_concentration, n_value, kd_range)
  File "/Users/tiago/working_PAPERS/SAXS_oligo_Kd/plotly_dash_tests/saxs_binding_equilibria_app_v3/models/monomer_oligomer.py", line 7, in calculate
    return MonomerOligomerCalculation.calculate(exp_saxs, mon_avg_int, dim_avg_int, concentration, n, kd_range)
  File "/Users/tiago/working_PAPERS/SAXS_oligo_Kd/plotly_dash_tests/saxs_binding_equilibria_app_v3/models/calculations.py", line 56, in calculate
    mon_avg_int = np.loadtxt(mon_avg_int, skiprows=1)
  File "/Users/tiago/opt/anaconda3/lib/python3.9/site-packages/numpy/lib/npyio.py", line 1373, in loadtxt
    arr = _read(fname, dtype=dtype, comment=comment, delimiter=delimiter,
  File "/Users/tiago/opt/anaconda3/lib/python3.9/site-packages/numpy/lib/npyio.py", line 1016, in _read
    arr = _load_from_filelike(
ValueError: could not convert string '│' to float64 at row 0, column 1.
2024-09-25 13:31:26,865 - saxs_analysis - ERROR - An error occurred: 1
Traceback (most recent call last):
  File "/Users/tiago/working_PAPERS/SAXS_oligo_Kd/plotly_dash_tests/saxs_binding_equilibria_app_v3/scripts/error_handling.py", line 42, in wrapper
    return func(*args, **kwargs)
  File "/Users/tiago/working_PAPERS/SAXS_oligo_Kd/plotly_dash_tests/saxs_binding_equilibria_app_v3/scripts/callbacks_analysis.py", line 111, in run_analysis
    n_value = n_input_children[1]['props']['value'] if n_input_children else None
KeyError: 1
2024-09-25 13:31:45,842 - saxs_analysis - ERROR - An error occurred: 1
Traceback (most recent call last):
  File "/Users/tiago/working_PAPERS/SAXS_oligo_Kd/plotly_dash_tests/saxs_binding_equilibria_app_v3/scripts/error_handling.py", line 42, in wrapper
    return func(*args, **kwargs)
  File "/Users/tiago/working_PAPERS/SAXS_oligo_Kd/plotly_dash_tests/saxs_binding_equilibria_app_v3/scripts/callbacks_analysis.py", line 111, in run_analysis
    n_value = n_input_children[1]['props']['value'] if n_input_children else None
KeyError: 1
2024-09-25 13:32:17,752 - saxs_analysis - ERROR - An error occurred: 1
Traceback (most recent call last):
  File "/Users/tiago/working_PAPERS/SAXS_oligo_Kd/plotly_dash_tests/saxs_binding_equilibria_app_v3/scripts/error_handling.py", line 42, in wrapper
    return func(*args, **kwargs)
  File "/Users/tiago/working_PAPERS/SAXS_oligo_Kd/plotly_dash_tests/saxs_binding_equilibria_app_v3/scripts/callbacks_analysis.py", line 111, in run_analysis
    n_value = n_input_children[1]['props']['value'] if n_input_children else None
KeyError: 1
2024-09-25 13:33:43,265 - saxs_analysis - ERROR - An error occurred: 1
Traceback (most recent call last):
  File "/Users/tiago/working_PAPERS/SAXS_oligo_Kd/plotly_dash_tests/saxs_binding_equilibria_app_v3/scripts/error_handling.py", line 42, in wrapper
    return func(*args, **kwargs)
  File "/Users/tiago/working_PAPERS/SAXS_oligo_Kd/plotly_dash_tests/saxs_binding_equilibria_app_v3/scripts/callbacks_analysis.py", line 111, in run_analysis
    n_value = n_input_children[1]['props']['value'] if n_input_children else None
KeyError: 1
2024-09-25 17:43:56,442 - saxs_analysis - ERROR - An error occurred: unsupported operand type(s) for /: 'NoneType' and 'int'
Traceback (most recent call last):
  File "/Users/tiago/working_PAPERS/SAXS_oligo_Kd/plotly_dash_tests/saxs_binding_equilibria_app_v3/scripts/error_handling.py", line 42, in wrapper
    return func(*args, **kwargs)
  File "/Users/tiago/working_PAPERS/SAXS_oligo_Kd/plotly_dash_tests/saxs_binding_equilibria_app_v3/scripts/callbacks_analysis.py", line 145, in run_analysis
    fraction_plot = create_fraction_plot(selected_kd, n_value, concentration_range, selected_model, receptor_concentration)
  File "/Users/tiago/working_PAPERS/SAXS_oligo_Kd/plotly_dash_tests/saxs_binding_equilibria_app_v3/plotting.py", line 121, in create_fraction_plot
    fractions = ProteinBindingCalculation.calculate_fractions(kd, concentration_range, n_value, receptor_concentration)
  File "/Users/tiago/working_PAPERS/SAXS_oligo_Kd/plotly_dash_tests/saxs_binding_equilibria_app_v3/models/calculations.py", line 161, in calculate_fractions
    receptor_concentration / n, ligand_concentration, kd, n)
TypeError: unsupported operand type(s) for /: 'NoneType' and 'int'
2024-09-25 17:43:57,138 - saxs_analysis - ERROR - An error occurred: unsupported operand type(s) for /: 'NoneType' and 'int'
Traceback (most recent call last):
  File "/Users/tiago/working_PAPERS/SAXS_oligo_Kd/plotly_dash_tests/saxs_binding_equilibria_app_v3/scripts/error_handling.py", line 42, in wrapper
    return func(*args, **kwargs)
  File "/Users/tiago/working_PAPERS/SAXS_oligo_Kd/plotly_dash_tests/saxs_binding_equilibria_app_v3/scripts/callbacks_analysis.py", line 145, in run_analysis
    fraction_plot = create_fraction_plot(selected_kd, n_value, concentration_range, selected_model, receptor_concentration)
  File "/Users/tiago/working_PAPERS/SAXS_oligo_Kd/plotly_dash_tests/saxs_binding_equilibria_app_v3/plotting.py", line 121, in create_fraction_plot
    fractions = ProteinBindingCalculation.calculate_fractions(kd, concentration_range, n_value, receptor_concentration)
  File "/Users/tiago/working_PAPERS/SAXS_oligo_Kd/plotly_dash_tests/saxs_binding_equilibria_app_v3/models/calculations.py", line 161, in calculate_fractions
    receptor_concentration / n, ligand_concentration, kd, n)
TypeError: unsupported operand type(s) for /: 'NoneType' and 'int'
2024-09-25 17:44:02,372 - saxs_analysis - ERROR - An error occurred: unsupported operand type(s) for /: 'NoneType' and 'int'
Traceback (most recent call last):
  File "/Users/tiago/working_PAPERS/SAXS_oligo_Kd/plotly_dash_tests/saxs_binding_equilibria_app_v3/scripts/error_handling.py", line 42, in wrapper
    return func(*args, **kwargs)
  File "/Users/tiago/working_PAPERS/SAXS_oligo_Kd/plotly_dash_tests/saxs_binding_equilibria_app_v3/scripts/callbacks_analysis.py", line 145, in run_analysis
    fraction_plot = create_fraction_plot(selected_kd, n_value, concentration_range, selected_model, receptor_concentration)
  File "/Users/tiago/working_PAPERS/SAXS_oligo_Kd/plotly_dash_tests/saxs_binding_equilibria_app_v3/plotting.py", line 121, in create_fraction_plot
    fractions = ProteinBindingCalculation.calculate_fractions(kd, concentration_range, n_value, receptor_concentration)
  File "/Users/tiago/working_PAPERS/SAXS_oligo_Kd/plotly_dash_tests/saxs_binding_equilibria_app_v3/models/calculations.py", line 161, in calculate_fractions
    receptor_concentration / n, ligand_concentration, kd, n)
TypeError: unsupported operand type(s) for /: 'NoneType' and 'int'
2024-09-25 17:44:07,290 - saxs_analysis - ERROR - An error occurred: unsupported operand type(s) for /: 'NoneType' and 'int'
Traceback (most recent call last):
  File "/Users/tiago/working_PAPERS/SAXS_oligo_Kd/plotly_dash_tests/saxs_binding_equilibria_app_v3/scripts/error_handling.py", line 42, in wrapper
    return func(*args, **kwargs)
  File "/Users/tiago/working_PAPERS/SAXS_oligo_Kd/plotly_dash_tests/saxs_binding_equilibria_app_v3/scripts/callbacks_analysis.py", line 145, in run_analysis
    fraction_plot = create_fraction_plot(selected_kd, n_value, concentration_range, selected_model, receptor_concentration)
  File "/Users/tiago/working_PAPERS/SAXS_oligo_Kd/plotly_dash_tests/saxs_binding_equilibria_app_v3/plotting.py", line 121, in create_fraction_plot
    fractions = ProteinBindingCalculation.calculate_fractions(kd, concentration_range, n_value, receptor_concentration)
  File "/Users/tiago/working_PAPERS/SAXS_oligo_Kd/plotly_dash_tests/saxs_binding_equilibria_app_v3/models/calculations.py", line 161, in calculate_fractions
    receptor_concentration / n, ligand_concentration, kd, n)
TypeError: unsupported operand type(s) for /: 'NoneType' and 'int'
2024-09-25 17:44:08,426 - saxs_analysis - ERROR - An error occurred: unsupported operand type(s) for /: 'NoneType' and 'int'
Traceback (most recent call last):
  File "/Users/tiago/working_PAPERS/SAXS_oligo_Kd/plotly_dash_tests/saxs_binding_equilibria_app_v3/scripts/error_handling.py", line 42, in wrapper
    return func(*args, **kwargs)
  File "/Users/tiago/working_PAPERS/SAXS_oligo_Kd/plotly_dash_tests/saxs_binding_equilibria_app_v3/scripts/callbacks_analysis.py", line 145, in run_analysis
    fraction_plot = create_fraction_plot(selected_kd, n_value, concentration_range, selected_model, receptor_concentration)
  File "/Users/tiago/working_PAPERS/SAXS_oligo_Kd/plotly_dash_tests/saxs_binding_equilibria_app_v3/plotting.py", line 121, in create_fraction_plot
    fractions = ProteinBindingCalculation.calculate_fractions(kd, concentration_range, n_value, receptor_concentration)
  File "/Users/tiago/working_PAPERS/SAXS_oligo_Kd/plotly_dash_tests/saxs_binding_equilibria_app_v3/models/calculations.py", line 161, in calculate_fractions
    receptor_concentration / n, ligand_concentration, kd, n)
TypeError: unsupported operand type(s) for /: 'NoneType' and 'int'
2024-09-25 17:44:09,473 - saxs_analysis - ERROR - An error occurred: unsupported operand type(s) for /: 'NoneType' and 'int'
Traceback (most recent call last):
  File "/Users/tiago/working_PAPERS/SAXS_oligo_Kd/plotly_dash_tests/saxs_binding_equilibria_app_v3/scripts/error_handling.py", line 42, in wrapper
    return func(*args, **kwargs)
  File "/Users/tiago/working_PAPERS/SAXS_oligo_Kd/plotly_dash_tests/saxs_binding_equilibria_app_v3/scripts/callbacks_analysis.py", line 145, in run_analysis
    fraction_plot = create_fraction_plot(selected_kd, n_value, concentration_range, selected_model, receptor_concentration)
  File "/Users/tiago/working_PAPERS/SAXS_oligo_Kd/plotly_dash_tests/saxs_binding_equilibria_app_v3/plotting.py", line 121, in create_fraction_plot
    fractions = ProteinBindingCalculation.calculate_fractions(kd, concentration_range, n_value, receptor_concentration)
  File "/Users/tiago/working_PAPERS/SAXS_oligo_Kd/plotly_dash_tests/saxs_binding_equilibria_app_v3/models/calculations.py", line 161, in calculate_fractions
    receptor_concentration / n, ligand_concentration, kd, n)
TypeError: unsupported operand type(s) for /: 'NoneType' and 'int'
2024-09-25 17:44:10,458 - saxs_analysis - ERROR - An error occurred: unsupported operand type(s) for /: 'NoneType' and 'int'
Traceback (most recent call last):
  File "/Users/tiago/working_PAPERS/SAXS_oligo_Kd/plotly_dash_tests/saxs_binding_equilibria_app_v3/scripts/error_handling.py", line 42, in wrapper
    return func(*args, **kwargs)
  File "/Users/tiago/working_PAPERS/SAXS_oligo_Kd/plotly_dash_tests/saxs_binding_equilibria_app_v3/scripts/callbacks_analysis.py", line 145, in run_analysis
    fraction_plot = create_fraction_plot(selected_kd, n_value, concentration_range, selected_model, receptor_concentration)
  File "/Users/tiago/working_PAPERS/SAXS_oligo_Kd/plotly_dash_tests/saxs_binding_equilibria_app_v3/plotting.py", line 121, in create_fraction_plot
    fractions = ProteinBindingCalculation.calculate_fractions(kd, concentration_range, n_value, receptor_concentration)
  File "/Users/tiago/working_PAPERS/SAXS_oligo_Kd/plotly_dash_tests/saxs_binding_equilibria_app_v3/models/calculations.py", line 161, in calculate_fractions
    receptor_concentration / n, ligand_concentration, kd, n)
TypeError: unsupported operand type(s) for /: 'NoneType' and 'int'
2024-09-25 18:56:32,259 - saxs_analysis - ERROR - KeyError: 'contents' in item 0
2024-09-25 18:56:32,259 - saxs_analysis - ERROR - KeyError: 'contents' in item 1
2024-09-25 19:37:04,274 - saxs_analysis - ERROR - KeyError: 'contents' in item 0
2024-09-25 19:37:04,274 - saxs_analysis - ERROR - KeyError: 'contents' in item 1
2024-09-25 19:45:21,698 - saxs_analysis - ERROR - Error in MonomerOligomerCalculation: could not convert string '│' to float64 at row 0, column 1.
2024-09-25 19:45:21,698 - saxs_analysis - ERROR - Error during analysis
ValueError: could not convert string to float: ''

The above exception was the direct cause of the following exception:

Traceback (most recent call last):
  File "/Users/tiago/working_PAPERS/SAXS_oligo_Kd/plotly_dash_tests/saxs_binding_equilibria_app_v3/scripts/callbacks_analysis.py", line 120, in run_analysis
    results, concentration_colors = process_saxs_data(selected_model, n_value, upload_container, theoretical_saxs_uploads, kd_range, receptor_concentration, upload_directory)
  File "/Users/tiago/working_PAPERS/SAXS_oligo_Kd/plotly_dash_tests/saxs_binding_equilibria_app_v3/scripts/callbacks_analysis.py", line 65, in process_saxs_data
    chi_squared_df = calculate_chi_squared(model, selected_model, exp_file_path, theoretical_saxs_uploads,
  File "/Users/tiago/working_PAPERS/SAXS_oligo_Kd/plotly_dash_tests/saxs_binding_equilibria_app_v3/scripts/callbacks_analysis.py", line 77, in calculate_chi_squared
    return model.calculate(exp_file_path, mon_file_path, dim_file_path, ligand_concentration, n_value, kd_range)
  File "/Users/tiago/working_PAPERS/SAXS_oligo_Kd/plotly_dash_tests/saxs_binding_equilibria_app_v3/models/monomer_oligomer.py", line 7, in calculate
    return MonomerOligomerCalculation.calculate(exp_saxs, mon_avg_int, dim_avg_int, concentration, n, kd_range)
  File "/Users/tiago/working_PAPERS/SAXS_oligo_Kd/plotly_dash_tests/saxs_binding_equilibria_app_v3/models/calculations.py", line 56, in calculate
    mon_avg_int = np.loadtxt(mon_avg_int, skiprows=1)
  File "/Users/tiago/opt/anaconda3/lib/python3.9/site-packages/numpy/lib/npyio.py", line 1373, in loadtxt
    arr = _read(fname, dtype=dtype, comment=comment, delimiter=delimiter,
  File "/Users/tiago/opt/anaconda3/lib/python3.9/site-packages/numpy/lib/npyio.py", line 1016, in _read
    arr = _load_from_filelike(
ValueError: could not convert string '│' to float64 at row 0, column 1.
2024-09-25 19:45:50,730 - saxs_analysis - ERROR - Error during analysis
Traceback (most recent call last):
  File "/Users/tiago/working_PAPERS/SAXS_oligo_Kd/plotly_dash_tests/saxs_binding_equilibria_app_v3/scripts/callbacks_analysis.py", line 120, in run_analysis
    results, concentration_colors = process_saxs_data(selected_model, n_value, upload_container, theoretical_saxs_uploads, kd_range, receptor_concentration, upload_directory)
  File "/Users/tiago/working_PAPERS/SAXS_oligo_Kd/plotly_dash_tests/saxs_binding_equilibria_app_v3/scripts/callbacks_analysis.py", line 65, in process_saxs_data
    chi_squared_df = calculate_chi_squared(model, selected_model, exp_file_path, theoretical_saxs_uploads,
  File "/Users/tiago/working_PAPERS/SAXS_oligo_Kd/plotly_dash_tests/saxs_binding_equilibria_app_v3/scripts/callbacks_analysis.py", line 73, in calculate_chi_squared
    mon_saxs = theoretical_saxs_uploads[0]['props']['contents']
KeyError: 'contents'
2024-09-26 12:57:17,006 - saxs_analysis - ERROR - Error in ProteinBindingCalculation: operands could not be broadcast together with shapes (0,2) (301,2) (0,2) 
2024-09-26 12:57:17,007 - saxs_analysis - ERROR - Error during analysis
Traceback (most recent call last):
  File "/Users/tiago/working_PAPERS/SAXS_oligo_Kd/plotly_dash_tests/saxs_binding_equilibria_app_v3/scripts/callbacks_analysis.py", line 120, in run_analysis
    results, concentration_colors = process_saxs_data(selected_model, n_value, upload_container, theoretical_saxs_uploads, kd_range, receptor_concentration, upload_directory)
  File "/Users/tiago/working_PAPERS/SAXS_oligo_Kd/plotly_dash_tests/saxs_binding_equilibria_app_v3/scripts/callbacks_analysis.py", line 65, in process_saxs_data
    chi_squared_df = calculate_chi_squared(model, selected_model, exp_file_path, theoretical_saxs_uploads,
  File "/Users/tiago/working_PAPERS/SAXS_oligo_Kd/plotly_dash_tests/saxs_binding_equilibria_app_v3/scripts/callbacks_analysis.py", line 83, in calculate_chi_squared
    return model.calculate(exp_file_path, theoretical_files, receptor_concentration, ligand_concentration, n_value, kd_range)
  File "/Users/tiago/working_PAPERS/SAXS_oligo_Kd/plotly_dash_tests/saxs_binding_equilibria_app_v3/models/protein_binding.py", line 9, in calculate
    return ProteinBindingCalculation.calculate(exp_saxs, theoretical_saxs_files, receptor_concentration, ligand_concentration, n, kd_range)
  File "/Users/tiago/working_PAPERS/SAXS_oligo_Kd/plotly_dash_tests/saxs_binding_equilibria_app_v3/models/calculations.py", line 223, in calculate
    theoretical_saxs += receptor_fracs[j] * np.loadtxt(theoretical_saxs_files[j], usecols=(0, 1))
ValueError: operands could not be broadcast together with shapes (0,2) (301,2) (0,2) 
2024-09-26 13:06:14,330 - saxs_analysis - ERROR - An error occurred: 
Traceback (most recent call last):
  File "/Users/tiago/working_PAPERS/SAXS_oligo_Kd/plotly_dash_tests/saxs_binding_equilibria_app_v3/scripts/error_handling.py", line 42, in wrapper
    return func(*args, **kwargs)
  File "/Users/tiago/working_PAPERS/SAXS_oligo_Kd/plotly_dash_tests/saxs_binding_equilibria_app_v3/scripts/callbacks_analysis.py", line 151, in run_analysis
    raise PreventUpdate
dash.exceptions.PreventUpdate
2024-09-26 13:07:52,167 - saxs_analysis - ERROR - An error occurred: local variable 'concentration_range' referenced before assignment
Traceback (most recent call last):
  File "/Users/tiago/working_PAPERS/SAXS_oligo_Kd/plotly_dash_tests/saxs_binding_equilibria_app_v3/scripts/error_handling.py", line 42, in wrapper
    return func(*args, **kwargs)
  File "/Users/tiago/working_PAPERS/SAXS_oligo_Kd/plotly_dash_tests/saxs_binding_equilibria_app_v3/scripts/callbacks_analysis.py", line 145, in run_analysis
    fraction_plot = create_fraction_plot(clicked_kd, n_value, concentration_range, selected_model, receptor_concentration)
UnboundLocalError: local variable 'concentration_range' referenced before assignment
2024-09-26 13:07:53,933 - saxs_analysis - ERROR - An error occurred: local variable 'concentration_range' referenced before assignment
Traceback (most recent call last):
  File "/Users/tiago/working_PAPERS/SAXS_oligo_Kd/plotly_dash_tests/saxs_binding_equilibria_app_v3/scripts/error_handling.py", line 42, in wrapper
    return func(*args, **kwargs)
  File "/Users/tiago/working_PAPERS/SAXS_oligo_Kd/plotly_dash_tests/saxs_binding_equilibria_app_v3/scripts/callbacks_analysis.py", line 145, in run_analysis
    fraction_plot = create_fraction_plot(clicked_kd, n_value, concentration_range, selected_model, receptor_concentration)
UnboundLocalError: local variable 'concentration_range' referenced before assignment
2024-09-26 13:07:54,551 - saxs_analysis - ERROR - An error occurred: local variable 'concentration_range' referenced before assignment
Traceback (most recent call last):
  File "/Users/tiago/working_PAPERS/SAXS_oligo_Kd/plotly_dash_tests/saxs_binding_equilibria_app_v3/scripts/error_handling.py", line 42, in wrapper
    return func(*args, **kwargs)
  File "/Users/tiago/working_PAPERS/SAXS_oligo_Kd/plotly_dash_tests/saxs_binding_equilibria_app_v3/scripts/callbacks_analysis.py", line 145, in run_analysis
    fraction_plot = create_fraction_plot(clicked_kd, n_value, concentration_range, selected_model, receptor_concentration)
UnboundLocalError: local variable 'concentration_range' referenced before assignment
2024-09-26 13:07:56,152 - saxs_analysis - ERROR - An error occurred: local variable 'concentration_range' referenced before assignment
Traceback (most recent call last):
  File "/Users/tiago/working_PAPERS/SAXS_oligo_Kd/plotly_dash_tests/saxs_binding_equilibria_app_v3/scripts/error_handling.py", line 42, in wrapper
    return func(*args, **kwargs)
  File "/Users/tiago/working_PAPERS/SAXS_oligo_Kd/plotly_dash_tests/saxs_binding_equilibria_app_v3/scripts/callbacks_analysis.py", line 145, in run_analysis
    fraction_plot = create_fraction_plot(clicked_kd, n_value, concentration_range, selected_model, receptor_concentration)
UnboundLocalError: local variable 'concentration_range' referenced before assignment
2024-09-26 13:07:57,195 - saxs_analysis - ERROR - An error occurred: local variable 'concentration_range' referenced before assignment
Traceback (most recent call last):
  File "/Users/tiago/working_PAPERS/SAXS_oligo_Kd/plotly_dash_tests/saxs_binding_equilibria_app_v3/scripts/error_handling.py", line 42, in wrapper
    return func(*args, **kwargs)
  File "/Users/tiago/working_PAPERS/SAXS_oligo_Kd/plotly_dash_tests/saxs_binding_equilibria_app_v3/scripts/callbacks_analysis.py", line 145, in run_analysis
    fraction_plot = create_fraction_plot(clicked_kd, n_value, concentration_range, selected_model, receptor_concentration)
UnboundLocalError: local variable 'concentration_range' referenced before assignment
2024-09-26 13:07:58,380 - saxs_analysis - ERROR - An error occurred: local variable 'concentration_range' referenced before assignment
Traceback (most recent call last):
  File "/Users/tiago/working_PAPERS/SAXS_oligo_Kd/plotly_dash_tests/saxs_binding_equilibria_app_v3/scripts/error_handling.py", line 42, in wrapper
    return func(*args, **kwargs)
  File "/Users/tiago/working_PAPERS/SAXS_oligo_Kd/plotly_dash_tests/saxs_binding_equilibria_app_v3/scripts/callbacks_analysis.py", line 145, in run_analysis
    fraction_plot = create_fraction_plot(clicked_kd, n_value, concentration_range, selected_model, receptor_concentration)
UnboundLocalError: local variable 'concentration_range' referenced before assignment
2024-09-26 13:07:59,139 - saxs_analysis - ERROR - An error occurred: local variable 'concentration_range' referenced before assignment
Traceback (most recent call last):
  File "/Users/tiago/working_PAPERS/SAXS_oligo_Kd/plotly_dash_tests/saxs_binding_equilibria_app_v3/scripts/error_handling.py", line 42, in wrapper
    return func(*args, **kwargs)
  File "/Users/tiago/working_PAPERS/SAXS_oligo_Kd/plotly_dash_tests/saxs_binding_equilibria_app_v3/scripts/callbacks_analysis.py", line 145, in run_analysis
    fraction_plot = create_fraction_plot(clicked_kd, n_value, concentration_range, selected_model, receptor_concentration)
UnboundLocalError: local variable 'concentration_range' referenced before assignment
2024-09-26 13:08:00,744 - saxs_analysis - ERROR - An error occurred: local variable 'concentration_range' referenced before assignment
Traceback (most recent call last):
  File "/Users/tiago/working_PAPERS/SAXS_oligo_Kd/plotly_dash_tests/saxs_binding_equilibria_app_v3/scripts/error_handling.py", line 42, in wrapper
    return func(*args, **kwargs)
  File "/Users/tiago/working_PAPERS/SAXS_oligo_Kd/plotly_dash_tests/saxs_binding_equilibria_app_v3/scripts/callbacks_analysis.py", line 145, in run_analysis
    fraction_plot = create_fraction_plot(clicked_kd, n_value, concentration_range, selected_model, receptor_concentration)
UnboundLocalError: local variable 'concentration_range' referenced before assignment
2024-09-26 13:08:57,126 - saxs_analysis - ERROR - An error occurred: 
Traceback (most recent call last):
  File "/Users/tiago/working_PAPERS/SAXS_oligo_Kd/plotly_dash_tests/saxs_binding_equilibria_app_v3/scripts/error_handling.py", line 41, in wrapper
    return func(*args, **kwargs)
  File "/Users/tiago/working_PAPERS/SAXS_oligo_Kd/plotly_dash_tests/saxs_binding_equilibria_app_v3/scripts/callbacks_analysis.py", line 111, in run_analysis
    raise PreventUpdate
dash.exceptions.PreventUpdate
2024-09-26 13:09:09,272 - saxs_analysis - ERROR - An error occurred: 
Traceback (most recent call last):
  File "/Users/tiago/working_PAPERS/SAXS_oligo_Kd/plotly_dash_tests/saxs_binding_equilibria_app_v3/scripts/error_handling.py", line 41, in wrapper
    return func(*args, **kwargs)
  File "/Users/tiago/working_PAPERS/SAXS_oligo_Kd/plotly_dash_tests/saxs_binding_equilibria_app_v3/scripts/callbacks_analysis.py", line 111, in run_analysis
    raise PreventUpdate
dash.exceptions.PreventUpdate
2024-09-26 13:09:46,090 - saxs_analysis - ERROR - An error occurred: local variable 'concentration_range' referenced before assignment
Traceback (most recent call last):
  File "/Users/tiago/working_PAPERS/SAXS_oligo_Kd/plotly_dash_tests/saxs_binding_equilibria_app_v3/scripts/error_handling.py", line 41, in wrapper
    return func(*args, **kwargs)
  File "/Users/tiago/working_PAPERS/SAXS_oligo_Kd/plotly_dash_tests/saxs_binding_equilibria_app_v3/scripts/callbacks_analysis.py", line 148, in run_analysis
    fraction_plot = create_fraction_plot(clicked_kd, n_value, concentration_range, selected_model, receptor_concentration)
UnboundLocalError: local variable 'concentration_range' referenced before assignment
2024-09-26 13:14:59,540 - saxs_analysis - ERROR - An error occurred: local variable 'concentration_range' referenced before assignment
Traceback (most recent call last):
  File "/Users/tiago/working_PAPERS/SAXS_oligo_Kd/plotly_dash_tests/saxs_binding_equilibria_app_v3/scripts/error_handling.py", line 41, in wrapper
    return func(*args, **kwargs)
  File "/Users/tiago/working_PAPERS/SAXS_oligo_Kd/plotly_dash_tests/saxs_binding_equilibria_app_v3/scripts/callbacks_analysis.py", line 148, in run_analysis
    fraction_plot = create_fraction_plot(clicked_kd, n_value, concentration_range, selected_model, receptor_concentration)
UnboundLocalError: local variable 'concentration_range' referenced before assignment
2024-09-26 13:15:14,741 - saxs_analysis - ERROR - An error occurred: local variable 'concentration_range' referenced before assignment
Traceback (most recent call last):
  File "/Users/tiago/working_PAPERS/SAXS_oligo_Kd/plotly_dash_tests/saxs_binding_equilibria_app_v3/scripts/error_handling.py", line 41, in wrapper
    return func(*args, **kwargs)
  File "/Users/tiago/working_PAPERS/SAXS_oligo_Kd/plotly_dash_tests/saxs_binding_equilibria_app_v3/scripts/callbacks_analysis.py", line 148, in run_analysis
    fraction_plot = create_fraction_plot(clicked_kd, n_value, concentration_range, selected_model, receptor_concentration)
UnboundLocalError: local variable 'concentration_range' referenced before assignment
2024-09-26 13:17:17,855 - saxs_analysis - ERROR - An error occurred: 
Traceback (most recent call last):
  File "/Users/tiago/working_PAPERS/SAXS_oligo_Kd/plotly_dash_tests/saxs_binding_equilibria_app_v3/scripts/error_handling.py", line 41, in wrapper
    return func(*args, **kwargs)
  File "/Users/tiago/working_PAPERS/SAXS_oligo_Kd/plotly_dash_tests/saxs_binding_equilibria_app_v3/scripts/callbacks_analysis.py", line 111, in run_analysis
    raise PreventUpdate
dash.exceptions.PreventUpdate
2024-09-26 13:18:27,134 - saxs_analysis - ERROR - Error in MonomerOligomerCalculation: could not convert string '│' to float64 at row 0, column 1.
2024-09-26 13:18:27,134 - saxs_analysis - ERROR - Error during analysis
ValueError: could not convert string to float: ''

The above exception was the direct cause of the following exception:

Traceback (most recent call last):
  File "/Users/tiago/working_PAPERS/SAXS_oligo_Kd/plotly_dash_tests/saxs_binding_equilibria_app_v3/scripts/callbacks_analysis.py", line 127, in run_analysis
    results, concentration_colors = process_saxs_data(selected_model, n_value, upload_container, theoretical_saxs_uploads, kd_range, receptor_concentration, upload_directory)
  File "/Users/tiago/working_PAPERS/SAXS_oligo_Kd/plotly_dash_tests/saxs_binding_equilibria_app_v3/scripts/callbacks_analysis.py", line 66, in process_saxs_data
    chi_squared_df = calculate_chi_squared(model, selected_model, exp_file_path, theoretical_saxs_uploads,
  File "/Users/tiago/working_PAPERS/SAXS_oligo_Kd/plotly_dash_tests/saxs_binding_equilibria_app_v3/scripts/callbacks_analysis.py", line 78, in calculate_chi_squared
    return model.calculate(exp_file_path, mon_file_path, dim_file_path, ligand_concentration, n_value, kd_range)
  File "/Users/tiago/working_PAPERS/SAXS_oligo_Kd/plotly_dash_tests/saxs_binding_equilibria_app_v3/models/monomer_oligomer.py", line 7, in calculate
    return MonomerOligomerCalculation.calculate(exp_saxs, mon_avg_int, dim_avg_int, concentration, n, kd_range)
  File "/Users/tiago/working_PAPERS/SAXS_oligo_Kd/plotly_dash_tests/saxs_binding_equilibria_app_v3/models/calculations.py", line 56, in calculate
    mon_avg_int = np.loadtxt(mon_avg_int, skiprows=1)
  File "/Users/tiago/opt/anaconda3/lib/python3.9/site-packages/numpy/lib/npyio.py", line 1373, in loadtxt
    arr = _read(fname, dtype=dtype, comment=comment, delimiter=delimiter,
  File "/Users/tiago/opt/anaconda3/lib/python3.9/site-packages/numpy/lib/npyio.py", line 1016, in _read
    arr = _load_from_filelike(
ValueError: could not convert string '│' to float64 at row 0, column 1.
2024-09-26 13:18:40,226 - saxs_analysis - ERROR - An error occurred: 
Traceback (most recent call last):
  File "/Users/tiago/working_PAPERS/SAXS_oligo_Kd/plotly_dash_tests/saxs_binding_equilibria_app_v3/scripts/error_handling.py", line 41, in wrapper
    return func(*args, **kwargs)
  File "/Users/tiago/working_PAPERS/SAXS_oligo_Kd/plotly_dash_tests/saxs_binding_equilibria_app_v3/scripts/callbacks_analysis.py", line 111, in run_analysis
    raise PreventUpdate
dash.exceptions.PreventUpdate
2024-09-26 13:19:56,968 - saxs_analysis - ERROR - An error occurred: 
Traceback (most recent call last):
  File "/Users/tiago/working_PAPERS/SAXS_oligo_Kd/plotly_dash_tests/saxs_binding_equilibria_app_v3/scripts/error_handling.py", line 42, in wrapper
    return func(*args, **kwargs)
  File "/Users/tiago/working_PAPERS/SAXS_oligo_Kd/plotly_dash_tests/saxs_binding_equilibria_app_v3/scripts/callbacks_analysis.py", line 111, in run_analysis
    raise PreventUpdate
dash.exceptions.PreventUpdate
2024-09-26 13:20:01,726 - saxs_analysis - ERROR - An error occurred: 
Traceback (most recent call last):
  File "/Users/tiago/working_PAPERS/SAXS_oligo_Kd/plotly_dash_tests/saxs_binding_equilibria_app_v3/scripts/error_handling.py", line 42, in wrapper
    return func(*args, **kwargs)
  File "/Users/tiago/working_PAPERS/SAXS_oligo_Kd/plotly_dash_tests/saxs_binding_equilibria_app_v3/scripts/callbacks_analysis.py", line 111, in run_analysis
    raise PreventUpdate
dash.exceptions.PreventUpdate
2024-09-26 13:21:48,222 - saxs_analysis - ERROR - An error occurred: 
Traceback (most recent call last):
  File "/Users/tiago/working_PAPERS/SAXS_oligo_Kd/plotly_dash_tests/saxs_binding_equilibria_app_v3/scripts/error_handling.py", line 42, in wrapper
    return func(*args, **kwargs)
  File "/Users/tiago/working_PAPERS/SAXS_oligo_Kd/plotly_dash_tests/saxs_binding_equilibria_app_v3/scripts/callbacks_analysis.py", line 111, in run_analysis
    raise PreventUpdate
dash.exceptions.PreventUpdate
2024-09-26 13:22:13,102 - saxs_analysis - ERROR - Error during analysis
Traceback (most recent call last):
  File "/Users/tiago/working_PAPERS/SAXS_oligo_Kd/plotly_dash_tests/saxs_binding_equilibria_app_v3/scripts/callbacks_analysis.py", line 132, in run_analysis
    fraction_plot = create_fraction_plot(best_kd, n_value, concentration_range, selected_model, receptor_concentration)
  File "/Users/tiago/working_PAPERS/SAXS_oligo_Kd/plotly_dash_tests/saxs_binding_equilibria_app_v3/plotting.py", line 110, in create_fraction_plot
    fractions = MonomerOligomerCalculation.calculate_fractions(kd, n_value, concentration_range)
  File "/Users/tiago/working_PAPERS/SAXS_oligo_Kd/plotly_dash_tests/saxs_binding_equilibria_app_v3/models/calculations.py", line 102, in calculate_fractions
    for concentration in concentration_range:
TypeError: 'int' object is not iterable
2024-09-26 13:22:34,791 - saxs_analysis - ERROR - An error occurred: 
Traceback (most recent call last):
  File "/Users/tiago/working_PAPERS/SAXS_oligo_Kd/plotly_dash_tests/saxs_binding_equilibria_app_v3/scripts/error_handling.py", line 42, in wrapper
    return func(*args, **kwargs)
  File "/Users/tiago/working_PAPERS/SAXS_oligo_Kd/plotly_dash_tests/saxs_binding_equilibria_app_v3/scripts/callbacks_analysis.py", line 111, in run_analysis
    raise PreventUpdate
dash.exceptions.PreventUpdate
2024-09-26 13:22:38,308 - saxs_analysis - ERROR - KeyError: 'contents' in item 0
2024-09-26 13:22:38,308 - saxs_analysis - ERROR - KeyError: 'contents' in item 1
2024-09-26 13:23:14,043 - saxs_analysis - ERROR - An error occurred: 
Traceback (most recent call last):
  File "/Users/tiago/working_PAPERS/SAXS_oligo_Kd/plotly_dash_tests/saxs_binding_equilibria_app_v3/scripts/error_handling.py", line 42, in wrapper
    return func(*args, **kwargs)
  File "/Users/tiago/working_PAPERS/SAXS_oligo_Kd/plotly_dash_tests/saxs_binding_equilibria_app_v3/scripts/callbacks_analysis.py", line 111, in run_analysis
    raise PreventUpdate
dash.exceptions.PreventUpdate
2024-09-26 14:57:47,232 - saxs_analysis - ERROR - An error occurred: 
Traceback (most recent call last):
  File "/Users/tiago/working_PAPERS/SAXS_oligo_Kd/plotly_dash_tests/saxs_binding_equilibria_app_v3/scripts/error_handling.py", line 42, in wrapper
    return func(*args, **kwargs)
  File "/Users/tiago/working_PAPERS/SAXS_oligo_Kd/plotly_dash_tests/saxs_binding_equilibria_app_v3/scripts/callbacks_analysis.py", line 111, in run_analysis
    raise PreventUpdate
dash.exceptions.PreventUpdate
2024-09-26 14:58:38,064 - saxs_analysis - ERROR - An error occurred: 
Traceback (most recent call last):
  File "/Users/tiago/working_PAPERS/SAXS_oligo_Kd/plotly_dash_tests/saxs_binding_equilibria_app_v3/scripts/error_handling.py", line 42, in wrapper
    return func(*args, **kwargs)
  File "/Users/tiago/working_PAPERS/SAXS_oligo_Kd/plotly_dash_tests/saxs_binding_equilibria_app_v3/scripts/callbacks_analysis.py", line 111, in run_analysis
    raise PreventUpdate
dash.exceptions.PreventUpdate
2024-09-26 15:00:08,332 - saxs_analysis - ERROR - An error occurred: 
Traceback (most recent call last):
  File "/Users/tiago/working_PAPERS/SAXS_oligo_Kd/plotly_dash_tests/saxs_binding_equilibria_app_v3/scripts/error_handling.py", line 42, in wrapper
    return func(*args, **kwargs)
  File "/Users/tiago/working_PAPERS/SAXS_oligo_Kd/plotly_dash_tests/saxs_binding_equilibria_app_v3/scripts/callbacks_analysis.py", line 111, in run_analysis
    raise PreventUpdate
dash.exceptions.PreventUpdate
2024-09-26 15:10:11,700 - saxs_analysis - ERROR - An error occurred: 
Traceback (most recent call last):
  File "/Users/tiago/working_PAPERS/SAXS_oligo_Kd/plotly_dash_tests/saxs_binding_equilibria_app_v3/scripts/error_handling.py", line 42, in wrapper
    return func(*args, **kwargs)
  File "/Users/tiago/working_PAPERS/SAXS_oligo_Kd/plotly_dash_tests/saxs_binding_equilibria_app_v3/scripts/callbacks_analysis.py", line 111, in run_analysis
    raise PreventUpdate
dash.exceptions.PreventUpdate
2024-09-26 15:10:16,454 - saxs_analysis - ERROR - An error occurred: 
Traceback (most recent call last):
  File "/Users/tiago/working_PAPERS/SAXS_oligo_Kd/plotly_dash_tests/saxs_binding_equilibria_app_v3/scripts/error_handling.py", line 42, in wrapper
    return func(*args, **kwargs)
  File "/Users/tiago/working_PAPERS/SAXS_oligo_Kd/plotly_dash_tests/saxs_binding_equilibria_app_v3/scripts/callbacks_analysis.py", line 111, in run_analysis
    raise PreventUpdate
dash.exceptions.PreventUpdate
2024-09-26 15:10:26,960 - saxs_analysis - ERROR - An error occurred: 
Traceback (most recent call last):
  File "/Users/tiago/working_PAPERS/SAXS_oligo_Kd/plotly_dash_tests/saxs_binding_equilibria_app_v3/scripts/error_handling.py", line 42, in wrapper
    return func(*args, **kwargs)
  File "/Users/tiago/working_PAPERS/SAXS_oligo_Kd/plotly_dash_tests/saxs_binding_equilibria_app_v3/scripts/callbacks_analysis.py", line 111, in run_analysis
    raise PreventUpdate
dash.exceptions.PreventUpdate
2024-09-26 15:10:45,222 - saxs_analysis - ERROR - An error occurred: 
Traceback (most recent call last):
  File "/Users/tiago/working_PAPERS/SAXS_oligo_Kd/plotly_dash_tests/saxs_binding_equilibria_app_v3/scripts/error_handling.py", line 42, in wrapper
    return func(*args, **kwargs)
  File "/Users/tiago/working_PAPERS/SAXS_oligo_Kd/plotly_dash_tests/saxs_binding_equilibria_app_v3/scripts/callbacks_analysis.py", line 111, in run_analysis
    raise PreventUpdate
dash.exceptions.PreventUpdate
2024-09-26 15:28:16,926 - saxs_analysis - ERROR - An error occurred: 
Traceback (most recent call last):
  File "/Users/tiago/working_PAPERS/SAXS_oligo_Kd/plotly_dash_tests/saxs_binding_equilibria_app_v3/scripts/error_handling.py", line 42, in wrapper
    return func(*args, **kwargs)
  File "/Users/tiago/working_PAPERS/SAXS_oligo_Kd/plotly_dash_tests/saxs_binding_equilibria_app_v3/scripts/callbacks_analysis.py", line 111, in run_analysis
    raise PreventUpdate
dash.exceptions.PreventUpdate
2024-09-26 15:30:14,997 - saxs_analysis - ERROR - An error occurred in run_analysis: 
Traceback (most recent call last):
  File "/Users/tiago/working_PAPERS/SAXS_oligo_Kd/plotly_dash_tests/saxs_binding_equilibria_app_v3/scripts/error_handling.py", line 42, in wrapper
    return func(*args, **kwargs)
  File "/Users/tiago/working_PAPERS/SAXS_oligo_Kd/plotly_dash_tests/saxs_binding_equilibria_app_v3/scripts/callbacks_analysis.py", line 111, in run_analysis
    raise PreventUpdate
dash.exceptions.PreventUpdate
2024-09-26 15:42:14,628 - saxs_analysis - ERROR - An error occurred in run_analysis: 
Traceback (most recent call last):
  File "/Users/tiago/working_PAPERS/SAXS_oligo_Kd/plotly_dash_tests/saxs_binding_equilibria_app_v3/scripts/error_handling.py", line 42, in wrapper
    return func(*args, **kwargs)
  File "/Users/tiago/working_PAPERS/SAXS_oligo_Kd/plotly_dash_tests/saxs_binding_equilibria_app_v3/scripts/callbacks_analysis.py", line 111, in run_analysis
    raise PreventUpdate
dash.exceptions.PreventUpdate
2024-09-26 15:42:53,360 - saxs_analysis - ERROR - An error occurred in run_analysis: 
Traceback (most recent call last):
  File "/Users/tiago/working_PAPERS/SAXS_oligo_Kd/plotly_dash_tests/saxs_binding_equilibria_app_v3/scripts/error_handling.py", line 42, in wrapper
    return func(*args, **kwargs)
  File "/Users/tiago/working_PAPERS/SAXS_oligo_Kd/plotly_dash_tests/saxs_binding_equilibria_app_v3/scripts/callbacks_analysis.py", line 111, in run_analysis
    raise PreventUpdate
dash.exceptions.PreventUpdate
2024-09-26 16:11:53,347 - saxs_analysis - ERROR - Error during analysis
Traceback (most recent call last):
  File "/Users/tiago/working_PAPERS/SAXS_oligo_Kd/plotly_dash_tests/saxs_binding_equilibria_app_v3/scripts/callbacks_analysis.py", line 129, in run_analysis
    results, concentration_colors = process_saxs_data(selected_model, n_value, upload_container, theoretical_saxs_uploads, kd_range, receptor_concentration, upload_directory)
  File "/Users/tiago/working_PAPERS/SAXS_oligo_Kd/plotly_dash_tests/saxs_binding_equilibria_app_v3/scripts/callbacks_analysis.py", line 66, in process_saxs_data
    chi_squared_df = calculate_chi_squared(model, selected_model, exp_file_path, theoretical_saxs_uploads,
  File "/Users/tiago/working_PAPERS/SAXS_oligo_Kd/plotly_dash_tests/saxs_binding_equilibria_app_v3/scripts/callbacks_analysis.py", line 74, in calculate_chi_squared
    mon_saxs = theoretical_saxs_uploads[0]['props']['contents']
KeyError: 'contents'
2024-09-26 17:45:10,663 - saxs_analysis - ERROR - Error during analysis
Traceback (most recent call last):
  File "/Users/tiago/working_PAPERS/SAXS_oligo_Kd/plotly_dash_tests/saxs_binding_equilibria_app_v3/scripts/callbacks_analysis.py", line 152, in run_analysis
    chi_squared_df = calculate_chi_squared(model, selected_model, exp_file_path, theoretical_saxs_uploads,
NameError: name 'model' is not defined
2024-09-26 17:45:18,207 - saxs_analysis - ERROR - Error during analysis
Traceback (most recent call last):
  File "/Users/tiago/working_PAPERS/SAXS_oligo_Kd/plotly_dash_tests/saxs_binding_equilibria_app_v3/scripts/callbacks_analysis.py", line 152, in run_analysis
    chi_squared_df = calculate_chi_squared(model, selected_model, exp_file_path, theoretical_saxs_uploads,
NameError: name 'model' is not defined
2024-09-26 17:47:50,738 - saxs_analysis - ERROR - Error during analysis
Traceback (most recent call last):
  File "/Users/tiago/working_PAPERS/SAXS_oligo_Kd/plotly_dash_tests/saxs_binding_equilibria_app_v3/scripts/callbacks_analysis.py", line 155, in run_analysis
    dash.callback_context.response.set_data({'progress': progress})
  File "/Users/tiago/opt/anaconda3/lib/python3.9/site-packages/werkzeug/wrappers/response.py", line 334, in set_data
    value = bytes(value)
TypeError: 'str' object cannot be interpreted as an integer
2024-09-26 18:37:59,972 - saxs_analysis - ERROR - Error during analysis
Traceback (most recent call last):
  File "/Users/tiago/working_PAPERS/SAXS_oligo_Kd/plotly_dash_tests/saxs_binding_equilibria_app_v3/scripts/callbacks_analysis.py", line 151, in run_analysis
    chi_squared_df = calculate_chi_squared(model, selected_model, exp_file_path, theoretical_saxs_uploads,
NameError: name 'model' is not defined
2024-09-26 18:49:06,018 - saxs_analysis - ERROR - An error occurred: 
Traceback (most recent call last):
  File "/Users/tiago/working_PAPERS/SAXS_oligo_Kd/plotly_dash_tests/saxs_binding_equilibria_app_v3/scripts/error_handling.py", line 42, in wrapper
    return func(*args, **kwargs)
  File "/Users/tiago/working_PAPERS/SAXS_oligo_Kd/plotly_dash_tests/saxs_binding_equilibria_app_v3/scripts/callbacks_analysis.py", line 111, in run_analysis
    raise PreventUpdate
dash.exceptions.PreventUpdate
2024-09-26 18:49:35,806 - saxs_analysis - ERROR - An error occurred: 
Traceback (most recent call last):
  File "/Users/tiago/working_PAPERS/SAXS_oligo_Kd/plotly_dash_tests/saxs_binding_equilibria_app_v3/scripts/error_handling.py", line 42, in wrapper
    return func(*args, **kwargs)
  File "/Users/tiago/working_PAPERS/SAXS_oligo_Kd/plotly_dash_tests/saxs_binding_equilibria_app_v3/scripts/callbacks_analysis.py", line 111, in run_analysis
    raise PreventUpdate
dash.exceptions.PreventUpdate
2024-09-26 18:50:16,112 - saxs_analysis - ERROR - An error occurred: 
Traceback (most recent call last):
  File "/Users/tiago/working_PAPERS/SAXS_oligo_Kd/plotly_dash_tests/saxs_binding_equilibria_app_v3/scripts/error_handling.py", line 42, in wrapper
    return func(*args, **kwargs)
  File "/Users/tiago/working_PAPERS/SAXS_oligo_Kd/plotly_dash_tests/saxs_binding_equilibria_app_v3/scripts/callbacks_analysis.py", line 111, in run_analysis
    raise PreventUpdate
dash.exceptions.PreventUpdate
2024-09-26 19:28:33,135 - saxs_analysis - ERROR - Error during analysis
Traceback (most recent call last):
  File "/Users/tiago/working_PAPERS/SAXS_oligo_Kd/plotly_dash_tests/saxs_binding_equilibria_app_v3/scripts/callbacks_analysis.py", line 129, in run_analysis
    return {'message': 'Analysis Complete!', 'is_error': False, 'timestamp': time.time()}, chi_squared_plot, fraction_plot, saxs_fit_plots
NameError: name 'time' is not defined
2024-09-26 19:28:33,136 - saxs_analysis - ERROR - An error occurred: name 'time' is not defined
Traceback (most recent call last):
  File "/Users/tiago/working_PAPERS/SAXS_oligo_Kd/plotly_dash_tests/saxs_binding_equilibria_app_v3/scripts/callbacks_analysis.py", line 129, in run_analysis
    return {'message': 'Analysis Complete!', 'is_error': False, 'timestamp': time.time()}, chi_squared_plot, fraction_plot, saxs_fit_plots
NameError: name 'time' is not defined

During handling of the above exception, another exception occurred:

Traceback (most recent call last):
  File "/Users/tiago/working_PAPERS/SAXS_oligo_Kd/plotly_dash_tests/saxs_binding_equilibria_app_v3/scripts/error_handling.py", line 42, in wrapper
    return func(*args, **kwargs)
  File "/Users/tiago/working_PAPERS/SAXS_oligo_Kd/plotly_dash_tests/saxs_binding_equilibria_app_v3/scripts/callbacks_analysis.py", line 134, in run_analysis
    return {'message': f'An error occurred during analysis: {str(e)}', 'is_error': True, 'timestamp': time.time()}, no_update, no_update, no_update
NameError: name 'time' is not defined
2024-09-26 19:29:45,701 - saxs_analysis - ERROR - An error occurred: 'str' object has no attribute '__name__'
Traceback (most recent call last):
  File "/Users/tiago/working_PAPERS/SAXS_oligo_Kd/plotly_dash_tests/saxs_binding_equilibria_app_v3/scripts/error_handling.py", line 42, in wrapper
    return func(*args, **kwargs)
  File "/Users/tiago/working_PAPERS/SAXS_oligo_Kd/plotly_dash_tests/saxs_binding_equilibria_app_v3/scripts/callbacks_analysis.py", line 244, in save_chi2_plot_as_csv
    return dcc.send_data_frame(csv_buffer.getvalue(), "chi2_plot.csv")
  File "/Users/tiago/opt/anaconda3/lib/python3.9/site-packages/dash/dcc/express.py", line 83, in send_data_frame
    name = writer.__name__
AttributeError: 'str' object has no attribute '__name__'
2024-09-26 19:30:06,179 - saxs_analysis - ERROR - An error occurred: 'str' object has no attribute '__name__'
Traceback (most recent call last):
  File "/Users/tiago/working_PAPERS/SAXS_oligo_Kd/plotly_dash_tests/saxs_binding_equilibria_app_v3/scripts/error_handling.py", line 42, in wrapper
    return func(*args, **kwargs)
  File "/Users/tiago/working_PAPERS/SAXS_oligo_Kd/plotly_dash_tests/saxs_binding_equilibria_app_v3/scripts/callbacks_analysis.py", line 266, in save_fraction_plot_as_csv
    return dcc.send_data_frame(csv_buffer.getvalue(), "fraction_plot.csv")
  File "/Users/tiago/opt/anaconda3/lib/python3.9/site-packages/dash/dcc/express.py", line 83, in send_data_frame
    name = writer.__name__
AttributeError: 'str' object has no attribute '__name__'
2024-09-27 11:24:07,929 - saxs_analysis - ERROR - An error occurred: unsupported operand type(s) for /: 'NoneType' and 'int'
Traceback (most recent call last):
  File "/Users/tiago/working_PAPERS/SAXS_oligo_Kd/plotly_dash_tests/saxs_binding_equilibria_app_v3/scripts/error_handling.py", line 42, in wrapper
    return func(*args, **kwargs)
  File "/Users/tiago/working_PAPERS/SAXS_oligo_Kd/plotly_dash_tests/saxs_binding_equilibria_app_v3/scripts/callbacks_analysis.py", line 144, in run_analysis
    fraction_plot = create_fraction_plot(clicked_kd, n_value, concentration_range, selected_model, receptor_concentration)
  File "/Users/tiago/working_PAPERS/SAXS_oligo_Kd/plotly_dash_tests/saxs_binding_equilibria_app_v3/plotting.py", line 121, in create_fraction_plot
    fractions = ProteinBindingCalculation.calculate_fractions(kd, concentration_range, n_value, receptor_concentration)
  File "/Users/tiago/working_PAPERS/SAXS_oligo_Kd/plotly_dash_tests/saxs_binding_equilibria_app_v3/models/calculations.py", line 161, in calculate_fractions
    receptor_concentration / n, ligand_concentration, kd, n)
TypeError: unsupported operand type(s) for /: 'NoneType' and 'int'
2024-09-30 10:50:11,562 - saxs_analysis - ERROR - An error occurred: list index out of range
Traceback (most recent call last):
  File "/Users/tiago/working_PAPERS/SAXS_oligo_Kd/plotly_dash_tests/saxs_binding_equilibria_app_v3/scripts/error_handling.py", line 42, in wrapper
    return func(*args, **kwargs)
  File "/Users/tiago/working_PAPERS/SAXS_oligo_Kd/plotly_dash_tests/saxs_binding_equilibria_app_v3/scripts/callbacks_analysis.py", line 239, in save_chi2_plot_as_csv
    df = pd.DataFrame({'Kd': figure['data'][0]['x'], 'Chi2': figure['data'][0]['y']})
IndexError: list index out of range
2024-09-30 12:00:38,604 - saxs_analysis - ERROR - An error occurred: list index out of range
Traceback (most recent call last):
  File "/Users/tiago/working_PAPERS/SAXS_oligo_Kd/plotly_dash_tests/saxs_binding_equilibria_app_v3/scripts/error_handling.py", line 42, in wrapper
    return func(*args, **kwargs)
  File "/Users/tiago/working_PAPERS/SAXS_oligo_Kd/plotly_dash_tests/saxs_binding_equilibria_app_v3/scripts/callbacks_analysis.py", line 239, in save_chi2_plot_as_csv
    df = pd.DataFrame({'Kd': figure['data'][0]['x'], 'Chi2': figure['data'][0]['y']})
IndexError: list index out of range
2024-09-30 12:13:48,842 - saxs_analysis - ERROR - KeyError: 'contents' in item 0
2024-09-30 12:13:48,842 - saxs_analysis - ERROR - KeyError: 'contents' in item 1
2024-09-30 16:55:53,795 - saxs_analysis - ERROR - Error during analysis
Traceback (most recent call last):
  File "/Users/tiago/working_PAPERS/SAXS_oligo_Kd/plotly_dash_tests/saxs_binding_equilibria_app_v3/scripts/callbacks_analysis.py", line 127, in run_analysis
    saxs_fit_plots = create_saxs_fit_plots(results, concentration_colors, upload_directory)
  File "/Users/tiago/working_PAPERS/SAXS_oligo_Kd/plotly_dash_tests/saxs_binding_equilibria_app_v3/plotting.py", line 54, in create_saxs_fit_plots
    plot_with_button = html.Div([save_button, plot])
NameError: name 'save_button' is not defined
2024-09-30 16:56:14,349 - saxs_analysis - ERROR - Error during analysis
Traceback (most recent call last):
  File "/Users/tiago/working_PAPERS/SAXS_oligo_Kd/plotly_dash_tests/saxs_binding_equilibria_app_v3/scripts/callbacks_analysis.py", line 127, in run_analysis
    saxs_fit_plots = create_saxs_fit_plots(results, concentration_colors, upload_directory)
  File "/Users/tiago/working_PAPERS/SAXS_oligo_Kd/plotly_dash_tests/saxs_binding_equilibria_app_v3/plotting.py", line 56, in create_saxs_fit_plots
    fit_plots_column1.append(plot_with_button)
NameError: name 'plot_with_button' is not defined
2024-09-30 16:56:36,380 - saxs_analysis - ERROR - Error during analysis
Traceback (most recent call last):
  File "/Users/tiago/working_PAPERS/SAXS_oligo_Kd/plotly_dash_tests/saxs_binding_equilibria_app_v3/scripts/callbacks_analysis.py", line 127, in run_analysis
    saxs_fit_plots = create_saxs_fit_plots(results, concentration_colors, upload_directory)
  File "/Users/tiago/working_PAPERS/SAXS_oligo_Kd/plotly_dash_tests/saxs_binding_equilibria_app_v3/plotting.py", line 56, in create_saxs_fit_plots
    fit_plots_column1.append(plot_with_button)
NameError: name 'plot_with_button' is not defined
2024-10-02 19:14:16,293 - saxs_analysis - ERROR - An error occurred: unsupported operand type(s) for /: 'NoneType' and 'int'
Traceback (most recent call last):
  File "/Users/tiago/working_PAPERS/SAXS_oligo_Kd/plotly_dash_tests/saxs_binding_equilibria_app_v3/scripts/error_handling.py", line 42, in wrapper
    return func(*args, **kwargs)
  File "/Users/tiago/working_PAPERS/SAXS_oligo_Kd/plotly_dash_tests/saxs_binding_equilibria_app_v3/scripts/callbacks_analysis.py", line 114, in run_analysis
    return handle_chi2_plot_click(click_data, n_value, conc_min, conc_max, conc_points, selected_model, receptor_concentration)
  File "/Users/tiago/working_PAPERS/SAXS_oligo_Kd/plotly_dash_tests/saxs_binding_equilibria_app_v3/scripts/callbacks_analysis.py", line 152, in handle_chi2_plot_click
    fraction_plot = create_fraction_plot(clicked_kd, n_value, concentration_range, selected_model, receptor_concentration)
  File "/Users/tiago/working_PAPERS/SAXS_oligo_Kd/plotly_dash_tests/saxs_binding_equilibria_app_v3/plotting.py", line 122, in create_fraction_plot
    fractions = ProteinBindingCalculation.calculate_fractions(kd, concentration_range, n_value, receptor_concentration)
  File "/Users/tiago/working_PAPERS/SAXS_oligo_Kd/plotly_dash_tests/saxs_binding_equilibria_app_v3/models/calculations.py", line 161, in calculate_fractions
    receptor_concentration / n, ligand_concentration, kd, n)
TypeError: unsupported operand type(s) for /: 'NoneType' and 'int'
2024-10-07 15:49:03,661 - saxs_analysis - ERROR - KeyError: 'contents' in item
2024-10-07 15:50:56,021 - saxs_analysis - ERROR - KeyError: 'contents' in item
2024-10-07 15:51:30,430 - saxs_analysis - ERROR - KeyError: 'contents' in item
2024-10-07 15:57:28,617 - saxs_analysis - ERROR - An error occurred: The truth value of an array with more than one element is ambiguous. Use a.any() or a.all()
Traceback (most recent call last):
  File "/Users/tiago/working_PAPERS/SAXS_oligo_Kd/plotly_dash_tests/saxs_binding_equilibria_app_v3/scripts/error_handling.py", line 42, in wrapper
    return func(*args, **kwargs)
  File "/Users/tiago/working_PAPERS/SAXS_oligo_Kd/plotly_dash_tests/saxs_binding_equilibria_app_v3/scripts/callbacks_analysis.py", line 111, in run_analysis
    return handle_run_analysis(n_clicks, selected_model, n_value, upload_container, theoretical_saxs_uploads,
  File "/Users/tiago/working_PAPERS/SAXS_oligo_Kd/plotly_dash_tests/saxs_binding_equilibria_app_v3/scripts/callbacks_analysis.py", line 128, in handle_run_analysis
    input_errors = validate_inputs(selected_model, n_value, upload_container, theoretical_saxs_uploads, kd_range, receptor_concentration)
  File "/Users/tiago/working_PAPERS/SAXS_oligo_Kd/plotly_dash_tests/saxs_binding_equilibria_app_v3/scripts/callbacks_analysis.py", line 32, in validate_inputs
    if not kd_range or len(kd_range) != 2 or kd_range[0] >= kd_range[1]:
ValueError: The truth value of an array with more than one element is ambiguous. Use a.any() or a.all()
2024-10-07 16:11:17,917 - saxs_analysis - ERROR - Error during analysis
Traceback (most recent call last):
  File "/Users/tiago/working_PAPERS/SAXS_oligo_Kd/plotly_dash_tests/saxs_binding_equilibria_app_v3/scripts/callbacks_analysis.py", line 133, in handle_run_analysis
    results, concentration_colors = process_saxs_data(selected_model, n_value, upload_container, theoretical_saxs_uploads, kd_range, receptor_concentration, upload_directory, kd_points)
  File "/Users/tiago/working_PAPERS/SAXS_oligo_Kd/plotly_dash_tests/saxs_binding_equilibria_app_v3/scripts/callbacks_analysis.py", line 52, in process_saxs_data
    chi_squared_df = calculate_chi_squared(model, selected_model, exp_file_path, theoretical_saxs_uploads,
  File "/Users/tiago/working_PAPERS/SAXS_oligo_Kd/plotly_dash_tests/saxs_binding_equilibria_app_v3/scripts/callbacks_analysis.py", line 71, in calculate_chi_squared
    return model.calculate(exp_file_path, mon_file_path, dim_file_path, ligand_concentration, n_value, kd_range, kd_points)
TypeError: calculate() takes 7 positional arguments but 8 were given
2024-10-07 16:11:46,156 - saxs_analysis - ERROR - Error during analysis
Traceback (most recent call last):
  File "/Users/tiago/working_PAPERS/SAXS_oligo_Kd/plotly_dash_tests/saxs_binding_equilibria_app_v3/scripts/callbacks_analysis.py", line 133, in handle_run_analysis
    results, concentration_colors = process_saxs_data(selected_model, n_value, upload_container, theoretical_saxs_uploads, kd_range, receptor_concentration, upload_directory, kd_points)
  File "/Users/tiago/working_PAPERS/SAXS_oligo_Kd/plotly_dash_tests/saxs_binding_equilibria_app_v3/scripts/callbacks_analysis.py", line 52, in process_saxs_data
    chi_squared_df = calculate_chi_squared(model, selected_model, exp_file_path, theoretical_saxs_uploads,
  File "/Users/tiago/working_PAPERS/SAXS_oligo_Kd/plotly_dash_tests/saxs_binding_equilibria_app_v3/scripts/callbacks_analysis.py", line 71, in calculate_chi_squared
    return model.calculate(exp_file_path, mon_file_path, dim_file_path, ligand_concentration, n_value, kd_range, kd_points)
TypeError: calculate() takes 7 positional arguments but 8 were given
2024-10-07 16:30:33,043 - saxs_analysis - ERROR - Error during analysis
Traceback (most recent call last):
  File "/Users/tiago/working_PAPERS/SAXS_oligo_Kd/plotly_dash_tests/saxs_binding_equilibria_app_v3/scripts/callbacks_analysis.py", line 135, in handle_run_analysis
    chi_squared_plot = create_chi_squared_plot(results, concentration_colors)
  File "/Users/tiago/working_PAPERS/SAXS_oligo_Kd/plotly_dash_tests/saxs_binding_equilibria_app_v3/plotting.py", line 15, in create_chi_squared_plot
    avg_chi_squared = chi_squared_df.groupby('kd')['chi2'].mean().reset_index()
AttributeError: 'list' object has no attribute 'groupby'
2024-10-08 12:49:33,239 - saxs_analysis - ERROR - Error in MonomerOligomerCalculation: geomspace() got an unexpected keyword argument 'decimals'
2024-10-08 12:49:33,239 - saxs_analysis - ERROR - Error during analysis
Traceback (most recent call last):
  File "/Users/tiago/working_PAPERS/SAXS_oligo_Kd/plotly_dash_tests/saxs_binding_equilibria_app_v3/scripts/callbacks_analysis.py", line 133, in handle_run_analysis
    results, concentration_colors = process_saxs_data(selected_model, n_value, upload_container, theoretical_saxs_uploads, kd_range, receptor_concentration, upload_directory, kd_points)
  File "/Users/tiago/working_PAPERS/SAXS_oligo_Kd/plotly_dash_tests/saxs_binding_equilibria_app_v3/scripts/callbacks_analysis.py", line 52, in process_saxs_data
    chi_squared_df = calculate_chi_squared(model, selected_model, exp_file_path, theoretical_saxs_uploads,
  File "/Users/tiago/working_PAPERS/SAXS_oligo_Kd/plotly_dash_tests/saxs_binding_equilibria_app_v3/scripts/callbacks_analysis.py", line 71, in calculate_chi_squared
    return model.calculate(exp_file_path, mon_file_path, dim_file_path, ligand_concentration, n_value, kd_range, kd_points)
  File "/Users/tiago/working_PAPERS/SAXS_oligo_Kd/plotly_dash_tests/saxs_binding_equilibria_app_v3/models/monomer_oligomer.py", line 7, in calculate
    return MonomerOligomerCalculation.calculate(exp_saxs, mon_avg_int, dim_avg_int, concentration, n, kd_range, kd_points)
  File "/Users/tiago/working_PAPERS/SAXS_oligo_Kd/plotly_dash_tests/saxs_binding_equilibria_app_v3/models/calculations.py", line 38, in calculate
    Kd_values = np.geomspace(kd_range[0], kd_range[1], num=kd_points, decimals=2)
TypeError: geomspace() got an unexpected keyword argument 'decimals'
2024-10-08 14:14:07,803 - saxs_analysis - ERROR - Error in ProteinBindingCalculation: name 'solve_binding_system_generalized' is not defined
2024-10-08 14:14:07,804 - saxs_analysis - ERROR - Error during analysis
Traceback (most recent call last):
  File "/Users/tiago/working_PAPERS/SAXS_oligo_Kd/plotly_dash_tests/saxs_binding_equilibria_app_v3/scripts/callbacks_analysis.py", line 133, in handle_run_analysis
    results, concentration_colors = process_saxs_data(selected_model, n_value, upload_container, theoretical_saxs_uploads, kd_range, receptor_concentration, upload_directory, kd_points)
  File "/Users/tiago/working_PAPERS/SAXS_oligo_Kd/plotly_dash_tests/saxs_binding_equilibria_app_v3/scripts/callbacks_analysis.py", line 52, in process_saxs_data
    chi_squared_df = calculate_chi_squared(model, selected_model, exp_file_path, theoretical_saxs_uploads,
  File "/Users/tiago/working_PAPERS/SAXS_oligo_Kd/plotly_dash_tests/saxs_binding_equilibria_app_v3/scripts/callbacks_analysis.py", line 77, in calculate_chi_squared
    return model.calculate(exp_file_path, theoretical_files, receptor_concentration, ligand_concentration, n_value, kd_range, kd_points)
  File "/Users/tiago/working_PAPERS/SAXS_oligo_Kd/plotly_dash_tests/saxs_binding_equilibria_app_v3/models/protein_binding.py", line 9, in calculate
    return ProteinBindingCalculation.calculate(exp_saxs, theoretical_saxs_files, receptor_concentration, ligand_concentration, n, kd_range, kd_points)
  File "/Users/tiago/working_PAPERS/SAXS_oligo_Kd/plotly_dash_tests/saxs_binding_equilibria_app_v3/models/calculations.py", line 184, in calculate
    receptor_vals, ligand_free = solve_binding_system_generalized(receptor_concentration / n, ligand_concentration, Kd, n)
NameError: name 'solve_binding_system_generalized' is not defined
2024-10-08 14:17:37,302 - saxs_analysis - ERROR - Error in MonomerOligomerCalculation: solve_system() missing 1 required positional argument: 'n'
2024-10-08 14:17:37,302 - saxs_analysis - ERROR - Error during analysis
Traceback (most recent call last):
  File "/Users/tiago/working_PAPERS/SAXS_oligo_Kd/plotly_dash_tests/saxs_binding_equilibria_app_v3/scripts/callbacks_analysis.py", line 133, in handle_run_analysis
    results, concentration_colors = process_saxs_data(selected_model, n_value, upload_container, theoretical_saxs_uploads, kd_range, receptor_concentration, upload_directory, kd_points)
  File "/Users/tiago/working_PAPERS/SAXS_oligo_Kd/plotly_dash_tests/saxs_binding_equilibria_app_v3/scripts/callbacks_analysis.py", line 52, in process_saxs_data
    chi_squared_df = calculate_chi_squared(model, selected_model, exp_file_path, theoretical_saxs_uploads,
  File "/Users/tiago/working_PAPERS/SAXS_oligo_Kd/plotly_dash_tests/saxs_binding_equilibria_app_v3/scripts/callbacks_analysis.py", line 71, in calculate_chi_squared
    return model.calculate(exp_file_path, mon_file_path, dim_file_path, ligand_concentration, n_value, kd_range, kd_points)
  File "/Users/tiago/working_PAPERS/SAXS_oligo_Kd/plotly_dash_tests/saxs_binding_equilibria_app_v3/models/monomer_oligomer.py", line 7, in calculate
    return MonomerOligomerCalculation.calculate(exp_saxs, mon_avg_int, dim_avg_int, concentration, n, kd_range, kd_points)
  File "/Users/tiago/working_PAPERS/SAXS_oligo_Kd/plotly_dash_tests/saxs_binding_equilibria_app_v3/models/calculations.py", line 65, in calculate
    M, O = MonomerOligomerCalculation.solve_system(concentration, Kd)
TypeError: solve_system() missing 1 required positional argument: 'n'
2024-10-08 15:30:58,733 - saxs_analysis - ERROR - Error during analysis
Traceback (most recent call last):
  File "/Users/tiago/working_PAPERS/SAXS_oligo_Kd/plotly_dash_tests/saxs_binding_equilibria_app_v3/scripts/callbacks_analysis.py", line 134, in handle_run_analysis
    results, concentration_colors = process_saxs_data(selected_model, n_value, upload_container, theoretical_saxs_uploads, kd_range, receptor_concentration, upload_directory, kd_points)
  File "/Users/tiago/working_PAPERS/SAXS_oligo_Kd/plotly_dash_tests/saxs_binding_equilibria_app_v3/scripts/callbacks_analysis.py", line 52, in process_saxs_data
    exp_file_path = save_file(f"exp_saxs_{i+1}.dat", exp_saxs, upload_directory)
  File "/Users/tiago/working_PAPERS/SAXS_oligo_Kd/plotly_dash_tests/saxs_binding_equilibria_app_v3/scripts/utils.py", line 10, in save_file
    with open(file_path, "wb") as fp:
FileNotFoundError: [Errno 2] No such file or directory: '/Users/tiago/working_PAPERS/SAXS_oligo_Kd/plotly_dash_tests/saxs_binding_equilibria_app_v3/data/exp_saxs_1.dat'
2024-10-08 15:30:58,733 - saxs_analysis - ERROR - Error during analysis
Traceback (most recent call last):
  File "/Users/tiago/working_PAPERS/SAXS_oligo_Kd/plotly_dash_tests/saxs_binding_equilibria_app_v3/scripts/callbacks_analysis.py", line 134, in handle_run_analysis
    results, concentration_colors = process_saxs_data(selected_model, n_value, upload_container, theoretical_saxs_uploads, kd_range, receptor_concentration, upload_directory, kd_points)
  File "/Users/tiago/working_PAPERS/SAXS_oligo_Kd/plotly_dash_tests/saxs_binding_equilibria_app_v3/scripts/callbacks_analysis.py", line 52, in process_saxs_data
    exp_file_path = save_file(f"exp_saxs_{i+1}.dat", exp_saxs, upload_directory)
  File "/Users/tiago/working_PAPERS/SAXS_oligo_Kd/plotly_dash_tests/saxs_binding_equilibria_app_v3/scripts/utils.py", line 10, in save_file
    with open(file_path, "wb") as fp:
FileNotFoundError: [Errno 2] No such file or directory: '/Users/tiago/working_PAPERS/SAXS_oligo_Kd/plotly_dash_tests/saxs_binding_equilibria_app_v3/data/exp_saxs_1.dat'
2024-10-08 15:47:18,815 - saxs_analysis - ERROR - An error occurred: name 'chi_squared_plot' is not defined
Traceback (most recent call last):
  File "/Users/tiago/working_PAPERS/SAXS_oligo_Kd/plotly_dash_tests/saxs_binding_equilibria_app_v3/scripts/error_handling.py", line 42, in wrapper
    return func(*args, **kwargs)
  File "/Users/tiago/working_PAPERS/SAXS_oligo_Kd/plotly_dash_tests/saxs_binding_equilibria_app_v3/scripts/callbacks_analysis.py", line 116, in run_analysis
    return {'message': 'Analysis Complete!', 'is_error': False}, chi_squared_plot, fraction_plot, saxs_fit_plots, progress, {'visibility': 'visible'}
NameError: name 'chi_squared_plot' is not defined
2024-10-09 16:44:08,270 - saxs_analysis - ERROR - KeyError: 'contents' in item
2024-10-09 16:44:08,271 - saxs_analysis - ERROR - KeyError: 'contents' in item
2024-10-10 19:27:16,806 - saxs_analysis - ERROR - KeyError: 'contents' in item
2024-10-10 19:27:16,806 - saxs_analysis - ERROR - KeyError: 'contents' in item
2024-10-10 19:27:28,629 - saxs_analysis - ERROR - KeyError: 'contents' in item
2024-10-10 19:27:28,630 - saxs_analysis - ERROR - KeyError: 'contents' in item
2024-10-10 19:28:54,782 - saxs_analysis - ERROR - KeyError: 'contents' in item
2024-10-10 19:28:54,782 - saxs_analysis - ERROR - KeyError: 'contents' in item
2024-10-10 19:29:17,298 - saxs_analysis - ERROR - KeyError: 'contents' in item
2024-10-10 19:29:17,298 - saxs_analysis - ERROR - KeyError: 'contents' in item
2024-10-11 10:41:53,340 - saxs_analysis - ERROR - KeyError: 'contents' in item
2024-10-11 10:45:20,288 - saxs_analysis - ERROR - KeyError: 'contents' in item
2024-10-11 10:46:52,344 - saxs_analysis - ERROR - KeyError: 'contents' in item
